Traceback (most recent call last):
  File "/home/poppymi2/public_html/app_food/passenger_wsgi.py", line 4, in <module>
    import django.core.handlers.wsgi
ModuleNotFoundError: No module named 'django'
Traceback (most recent call last):
  File "/home/poppymi2/public_html/app_food/passenger_wsgi.py", line 4, in <module>
    import django.core.handlers.wsgi
ModuleNotFoundError: No module named 'django'
[UID:1745][2920710] Child process with pid: 2920723 was killed by signal: 15, core dumped: no
Traceback (most recent call last):
  File "/home/poppymi2/public_html/app_food/passenger_wsgi.py", line 4, in <module>
    import django.core.handlers.wsgi
ModuleNotFoundError: No module named 'django'
Traceback (most recent call last):
  File "/home/poppymi2/public_html/app_food/passenger_wsgi.py", line 4, in <module>
    import django.core.handlers.wsgi
ModuleNotFoundError: No module named 'django'
[UID:1745][2942314] Child process with pid: 2942320 was killed by signal: 15, core dumped: no
Traceback (most recent call last):
  File "/home/poppymi2/public_html/app_food/passenger_wsgi.py", line 4, in <module>
    import django.core.handlers.wsgi
ModuleNotFoundError: No module named 'django'
Traceback (most recent call last):
  File "/home/poppymi2/public_html/app_food/passenger_wsgi.py", line 4, in <module>
    import django.core.handlers.wsgi
ModuleNotFoundError: No module named 'django'
[UID:1745][2943366] Child process with pid: 2943374 was killed by signal: 15, core dumped: no
Traceback (most recent call last):
  File "/home/poppymi2/public_html/app_food/passenger_wsgi.py", line 4, in <module>
    import django.core.handlers.wsgi
ModuleNotFoundError: No module named 'django'
Traceback (most recent call last):
  File "/home/poppymi2/public_html/app_food/passenger_wsgi.py", line 4, in <module>
    import django.core.handlers.wsgi
ModuleNotFoundError: No module named 'django'
[UID:1745][2952041] Child process with pid: 2952044 was killed by signal: 15, core dumped: no
Traceback (most recent call last):
  File "/home/poppymi2/public_html/app_food/passenger_wsgi.py", line 4, in <module>
    import django.core.handlers.wsgi
ModuleNotFoundError: No module named 'django'
[UID:1745][2952041] Child process with pid: 2952051 was killed by signal: 15, core dumped: no
Traceback (most recent call last):
  File "/home/poppymi2/public_html/app_food/passenger_wsgi.py", line 4, in <module>
    import django.core.handlers.wsgi
ModuleNotFoundError: No module named 'django'
[UID:1745][2952041] Child process with pid: 2952090 was killed by signal: 15, core dumped: no
Traceback (most recent call last):
  File "/home/poppymi2/public_html/app_food/passenger_wsgi.py", line 4, in <module>
    import django.core.handlers.wsgi
ModuleNotFoundError: No module named 'django'
[UID:1745][2952041] Child process with pid: 2952103 was killed by signal: 15, core dumped: no
Traceback (most recent call last):
  File "/home/poppymi2/public_html/app_food/passenger_wsgi.py", line 4, in <module>
    import django.core.handlers.wsgi
ModuleNotFoundError: No module named 'django'
[UID:1745][2952041] Child process with pid: 2957111 was killed by signal: 15, core dumped: no
Traceback (most recent call last):
  File "/home/poppymi2/public_html/app_food/passenger_wsgi.py", line 4, in <module>
    import django.core.handlers.wsgi
ModuleNotFoundError: No module named 'django'
Traceback (most recent call last):
  File "/home/poppymi2/public_html/app_food/passenger_wsgi.py", line 4, in <module>
    import django.core.handlers.wsgi
ModuleNotFoundError: No module named 'django'
[UID:1745][2957472] Child process with pid: 2957483 was killed by signal: 15, core dumped: no
Traceback (most recent call last):
  File "/home/poppymi2/public_html/app_food/passenger_wsgi.py", line 4, in <module>
    import django.core.handlers.wsgi
ModuleNotFoundError: No module named 'django'
Traceback (most recent call last):
  File "/home/poppymi2/public_html/app_food/passenger_wsgi.py", line 4, in <module>
    import django.core.handlers.wsgi
ModuleNotFoundError: No module named 'django'
[UID:1745][2960777] Child process with pid: 2960780 was killed by signal: 15, core dumped: no
Traceback (most recent call last):
  File "/home/poppymi2/public_html/app_food/passenger_wsgi.py", line 4, in <module>
    import django.core.handlers.wsgi
ModuleNotFoundError: No module named 'django'
[UID:1745][2960777] Child process with pid: 2960781 was killed by signal: 15, core dumped: no
Traceback (most recent call last):
  File "/home/poppymi2/public_html/app_food/passenger_wsgi.py", line 4, in <module>
    import django.core.handlers.wsgi
ModuleNotFoundError: No module named 'django'
Traceback (most recent call last):
  File "/home/poppymi2/public_html/app_food/passenger_wsgi.py", line 4, in <module>
    import django.core.handlers.wsgi
ModuleNotFoundError: No module named 'django'
[UID:1745][2961276] Child process with pid: 2961286 was killed by signal: 15, core dumped: no
Traceback (most recent call last):
  File "/home/poppymi2/public_html/app_food/passenger_wsgi.py", line 4, in <module>
    import django.core.handlers.wsgi
ModuleNotFoundError: No module named 'django'
[UID:1745][2961276] Child process with pid: 2961359 was killed by signal: 15, core dumped: no
Traceback (most recent call last):
  File "/home/poppymi2/public_html/app_food/passenger_wsgi.py", line 4, in <module>
    import django.core.handlers.wsgi
ModuleNotFoundError: No module named 'django'
[UID:1745][2961276] Child process with pid: 2961398 was killed by signal: 15, core dumped: no
Traceback (most recent call last):
  File "/home/poppymi2/public_html/app_food/passenger_wsgi.py", line 4, in <module>
    import django.core.handlers.wsgi
ModuleNotFoundError: No module named 'django'
[UID:1745][2961276] Child process with pid: 2961468 was killed by signal: 15, core dumped: no
Traceback (most recent call last):
  File "/home/poppymi2/public_html/app_food/passenger_wsgi.py", line 5, in <module>
    from django.core.wsgi import get_wsgi_application
ModuleNotFoundError: No module named 'django'
Traceback (most recent call last):
  File "/home/poppymi2/public_html/app_food/passenger_wsgi.py", line 5, in <module>
    from django.core.wsgi import get_wsgi_application
ModuleNotFoundError: No module named 'django'
[UID:1745][2963179] Child process with pid: 2963185 was killed by signal: 15, core dumped: no
Traceback (most recent call last):
  File "/home/poppymi2/public_html/app_food/passenger_wsgi.py", line 8, in <module>
    wsgi = imp.load_source('wsgi', 'foodaApp/wsgi.py')
           ^^^^^^^^^^^^^^^^^^^^^^^^^^^^^^^^^^^^^^^^^^^
  File "/opt/alt/python311/lib64/python3.11/imp.py", line 172, in load_source
    module = _load(spec)
             ^^^^^^^^^^^
  File "<frozen importlib._bootstrap>", line 721, in _load
  File "<frozen importlib._bootstrap>", line 690, in _load_unlocked
  File "<frozen importlib._bootstrap_external>", line 940, in exec_module
  File "<frozen importlib._bootstrap>", line 241, in _call_with_frames_removed
  File "foodaApp/wsgi.py", line 12, in <module>
    from django.core.wsgi import get_wsgi_application
ModuleNotFoundError: No module named 'django'
Traceback (most recent call last):
  File "/home/poppymi2/public_html/app_food/passenger_wsgi.py", line 8, in <module>
    wsgi = imp.load_source('wsgi', 'foodaApp/wsgi.py')
           ^^^^^^^^^^^^^^^^^^^^^^^^^^^^^^^^^^^^^^^^^^^
  File "/opt/alt/python311/lib64/python3.11/imp.py", line 172, in load_source
    module = _load(spec)
             ^^^^^^^^^^^
  File "<frozen importlib._bootstrap>", line 721, in _load
  File "<frozen importlib._bootstrap>", line 690, in _load_unlocked
  File "<frozen importlib._bootstrap_external>", line 940, in exec_module
  File "<frozen importlib._bootstrap>", line 241, in _call_with_frames_removed
  File "foodaApp/wsgi.py", line 12, in <module>
    from django.core.wsgi import get_wsgi_application
ModuleNotFoundError: No module named 'django'
[UID:1745][2970026] Child process with pid: 2970050 was killed by signal: 15, core dumped: no
Traceback (most recent call last):
  File "/home/poppymi2/public_html/app_food/passenger_wsgi.py", line 8, in <module>
    wsgi = imp.load_source('wsgi', 'foodaApp/wsgi.py')
           ^^^^^^^^^^^^^^^^^^^^^^^^^^^^^^^^^^^^^^^^^^^
  File "/opt/alt/python311/lib64/python3.11/imp.py", line 172, in load_source
    module = _load(spec)
             ^^^^^^^^^^^
  File "<frozen importlib._bootstrap>", line 721, in _load
  File "<frozen importlib._bootstrap>", line 690, in _load_unlocked
  File "<frozen importlib._bootstrap_external>", line 940, in exec_module
  File "<frozen importlib._bootstrap>", line 241, in _call_with_frames_removed
  File "foodaApp/wsgi.py", line 12, in <module>
    from django.core.wsgi import get_wsgi_application
ModuleNotFoundError: No module named 'django'
[UID:1745][2970026] Child process with pid: 2970139 was killed by signal: 15, core dumped: no
Traceback (most recent call last):
  File "/home/poppymi2/public_html/app_food/passenger_wsgi.py", line 8, in <module>
    wsgi = imp.load_source('wsgi', 'foodaApp/wsgi.py')
           ^^^^^^^^^^^^^^^^^^^^^^^^^^^^^^^^^^^^^^^^^^^
  File "/opt/alt/python311/lib64/python3.11/imp.py", line 172, in load_source
    module = _load(spec)
             ^^^^^^^^^^^
  File "<frozen importlib._bootstrap>", line 721, in _load
  File "<frozen importlib._bootstrap>", line 690, in _load_unlocked
  File "<frozen importlib._bootstrap_external>", line 940, in exec_module
  File "<frozen importlib._bootstrap>", line 241, in _call_with_frames_removed
  File "foodaApp/wsgi.py", line 12, in <module>
    from django.core.wsgi import get_wsgi_application
ModuleNotFoundError: No module named 'django'
[UID:1745][2970026] Child process with pid: 2970305 was killed by signal: 15, core dumped: no
Traceback (most recent call last):
  File "/home/poppymi2/public_html/app_food/passenger_wsgi.py", line 8, in <module>
    wsgi = imp.load_source('wsgi', 'foodaApp/wsgi.py')
           ^^^^^^^^^^^^^^^^^^^^^^^^^^^^^^^^^^^^^^^^^^^
  File "/opt/alt/python311/lib64/python3.11/imp.py", line 172, in load_source
    module = _load(spec)
             ^^^^^^^^^^^
  File "<frozen importlib._bootstrap>", line 721, in _load
  File "<frozen importlib._bootstrap>", line 690, in _load_unlocked
  File "<frozen importlib._bootstrap_external>", line 940, in exec_module
  File "<frozen importlib._bootstrap>", line 241, in _call_with_frames_removed
  File "foodaApp/wsgi.py", line 12, in <module>
    from django.core.wsgi import get_wsgi_application
ModuleNotFoundError: No module named 'django'
Traceback (most recent call last):
  File "/home/poppymi2/public_html/app_food/passenger_wsgi.py", line 8, in <module>
    wsgi = imp.load_source('wsgi', 'foodaApp/wsgi.py')
           ^^^^^^^^^^^^^^^^^^^^^^^^^^^^^^^^^^^^^^^^^^^
  File "/opt/alt/python311/lib64/python3.11/imp.py", line 172, in load_source
    module = _load(spec)
             ^^^^^^^^^^^
  File "<frozen importlib._bootstrap>", line 721, in _load
  File "<frozen importlib._bootstrap>", line 690, in _load_unlocked
  File "<frozen importlib._bootstrap_external>", line 940, in exec_module
  File "<frozen importlib._bootstrap>", line 241, in _call_with_frames_removed
  File "foodaApp/wsgi.py", line 12, in <module>
    from django.core.wsgi import get_wsgi_application
ModuleNotFoundError: No module named 'django'
[UID:1745][2973982] Child process with pid: 2973994 was killed by signal: 15, core dumped: no
Traceback (most recent call last):
  File "/home/poppymi2/public_html/app_food/passenger_wsgi.py", line 8, in <module>
    wsgi = imp.load_source('wsgi', 'foodaApp/wsgi.py')
           ^^^^^^^^^^^^^^^^^^^^^^^^^^^^^^^^^^^^^^^^^^^
  File "/opt/alt/python311/lib64/python3.11/imp.py", line 172, in load_source
    module = _load(spec)
             ^^^^^^^^^^^
  File "<frozen importlib._bootstrap>", line 721, in _load
  File "<frozen importlib._bootstrap>", line 690, in _load_unlocked
  File "<frozen importlib._bootstrap_external>", line 940, in exec_module
  File "<frozen importlib._bootstrap>", line 241, in _call_with_frames_removed
  File "foodaApp/wsgi.py", line 12, in <module>
    from django.core.wsgi import get_wsgi_application
ModuleNotFoundError: No module named 'django'
[UID:1745][2973982] Child process with pid: 2974020 was killed by signal: 15, core dumped: no
Traceback (most recent call last):
  File "/home/poppymi2/public_html/app_food/passenger_wsgi.py", line 8, in <module>
    wsgi = imp.load_source('wsgi', 'foodaApp/wsgi.py')
           ^^^^^^^^^^^^^^^^^^^^^^^^^^^^^^^^^^^^^^^^^^^
  File "/opt/alt/python311/lib64/python3.11/imp.py", line 172, in load_source
    module = _load(spec)
             ^^^^^^^^^^^
  File "<frozen importlib._bootstrap>", line 721, in _load
  File "<frozen importlib._bootstrap>", line 690, in _load_unlocked
  File "<frozen importlib._bootstrap_external>", line 940, in exec_module
  File "<frozen importlib._bootstrap>", line 241, in _call_with_frames_removed
  File "foodaApp/wsgi.py", line 12, in <module>
    from django.core.wsgi import get_wsgi_application
ModuleNotFoundError: No module named 'django'
[UID:1745][2973982] Child process with pid: 2974050 was killed by signal: 15, core dumped: no
Traceback (most recent call last):
  File "/home/poppymi2/public_html/app_food/passenger_wsgi.py", line 8, in <module>
    wsgi = imp.load_source('wsgi', 'foodaApp/wsgi.py')
           ^^^^^^^^^^^^^^^^^^^^^^^^^^^^^^^^^^^^^^^^^^^
  File "/opt/alt/python311/lib64/python3.11/imp.py", line 172, in load_source
    module = _load(spec)
             ^^^^^^^^^^^
  File "<frozen importlib._bootstrap>", line 721, in _load
  File "<frozen importlib._bootstrap>", line 690, in _load_unlocked
  File "<frozen importlib._bootstrap_external>", line 940, in exec_module
  File "<frozen importlib._bootstrap>", line 241, in _call_with_frames_removed
  File "foodaApp/wsgi.py", line 12, in <module>
    from django.core.wsgi import get_wsgi_application
ModuleNotFoundError: No module named 'django'
Traceback (most recent call last):
  File "/home/poppymi2/public_html/app_food/passenger_wsgi.py", line 8, in <module>
    wsgi = imp.load_source('wsgi', 'foodaApp/wsgi.py')
           ^^^^^^^^^^^^^^^^^^^^^^^^^^^^^^^^^^^^^^^^^^^
  File "/opt/alt/python311/lib64/python3.11/imp.py", line 172, in load_source
    module = _load(spec)
             ^^^^^^^^^^^
  File "<frozen importlib._bootstrap>", line 721, in _load
  File "<frozen importlib._bootstrap>", line 690, in _load_unlocked
  File "<frozen importlib._bootstrap_external>", line 940, in exec_module
  File "<frozen importlib._bootstrap>", line 241, in _call_with_frames_removed
  File "foodaApp/wsgi.py", line 12, in <module>
    from django.core.wsgi import get_wsgi_application
ModuleNotFoundError: No module named 'django'
[UID:1745][2985118] Child process with pid: 2985122 was killed by signal: 15, core dumped: no
Traceback (most recent call last):
  File "/home/poppymi2/public_html/app_food/passenger_wsgi.py", line 8, in <module>
    wsgi = imp.load_source('wsgi', 'foodaApp/wsgi.py')
           ^^^^^^^^^^^^^^^^^^^^^^^^^^^^^^^^^^^^^^^^^^^
  File "/opt/alt/python311/lib64/python3.11/imp.py", line 172, in load_source
    module = _load(spec)
             ^^^^^^^^^^^
  File "<frozen importlib._bootstrap>", line 721, in _load
  File "<frozen importlib._bootstrap>", line 690, in _load_unlocked
  File "<frozen importlib._bootstrap_external>", line 940, in exec_module
  File "<frozen importlib._bootstrap>", line 241, in _call_with_frames_removed
  File "foodaApp/wsgi.py", line 12, in <module>
    from django.core.wsgi import get_wsgi_application
ModuleNotFoundError: No module named 'django'
Traceback (most recent call last):
  File "/home/poppymi2/public_html/app_food/passenger_wsgi.py", line 8, in <module>
    wsgi = imp.load_source('wsgi', 'foodaApp/wsgi.py')
           ^^^^^^^^^^^^^^^^^^^^^^^^^^^^^^^^^^^^^^^^^^^
  File "/opt/alt/python311/lib64/python3.11/imp.py", line 172, in load_source
    module = _load(spec)
             ^^^^^^^^^^^
  File "<frozen importlib._bootstrap>", line 721, in _load
  File "<frozen importlib._bootstrap>", line 690, in _load_unlocked
  File "<frozen importlib._bootstrap_external>", line 940, in exec_module
  File "<frozen importlib._bootstrap>", line 241, in _call_with_frames_removed
  File "foodaApp/wsgi.py", line 12, in <module>
    from django.core.wsgi import get_wsgi_application
ModuleNotFoundError: No module named 'django'
[UID:1745][2985144] Child process with pid: 2985151 was killed by signal: 15, core dumped: no
Traceback (most recent call last):
  File "/home/poppymi2/public_html/app_food/passenger_wsgi.py", line 8, in <module>
    wsgi = imp.load_source('wsgi', 'foodaApp/wsgi.py')
           ^^^^^^^^^^^^^^^^^^^^^^^^^^^^^^^^^^^^^^^^^^^
  File "/opt/alt/python311/lib64/python3.11/imp.py", line 172, in load_source
    module = _load(spec)
             ^^^^^^^^^^^
  File "<frozen importlib._bootstrap>", line 721, in _load
  File "<frozen importlib._bootstrap>", line 690, in _load_unlocked
  File "<frozen importlib._bootstrap_external>", line 940, in exec_module
  File "<frozen importlib._bootstrap>", line 241, in _call_with_frames_removed
  File "foodaApp/wsgi.py", line 12, in <module>
    from django.core.wsgi import get_wsgi_application
ModuleNotFoundError: No module named 'django'
[UID:1745][2985144] Child process with pid: 2986558 was killed by signal: 15, core dumped: no
Traceback (most recent call last):
  File "/home/poppymi2/public_html/app_food/passenger_wsgi.py", line 8, in <module>
    wsgi = imp.load_source('wsgi', 'foodaApp/wsgi.py')
           ^^^^^^^^^^^^^^^^^^^^^^^^^^^^^^^^^^^^^^^^^^^
  File "/opt/alt/python311/lib64/python3.11/imp.py", line 172, in load_source
    module = _load(spec)
             ^^^^^^^^^^^
  File "<frozen importlib._bootstrap>", line 721, in _load
  File "<frozen importlib._bootstrap>", line 690, in _load_unlocked
  File "<frozen importlib._bootstrap_external>", line 940, in exec_module
  File "<frozen importlib._bootstrap>", line 241, in _call_with_frames_removed
  File "foodaApp/wsgi.py", line 12, in <module>
    from django.core.wsgi import get_wsgi_application
ModuleNotFoundError: No module named 'django'
[UID:1745][2985144] Child process with pid: 2986698 was killed by signal: 15, core dumped: no
Traceback (most recent call last):
  File "/home/poppymi2/public_html/app_food/passenger_wsgi.py", line 8, in <module>
    wsgi = imp.load_source('wsgi', 'foodaApp/wsgi.py')
           ^^^^^^^^^^^^^^^^^^^^^^^^^^^^^^^^^^^^^^^^^^^
  File "/opt/alt/python311/lib64/python3.11/imp.py", line 172, in load_source
    module = _load(spec)
             ^^^^^^^^^^^
  File "<frozen importlib._bootstrap>", line 721, in _load
  File "<frozen importlib._bootstrap>", line 690, in _load_unlocked
  File "<frozen importlib._bootstrap_external>", line 940, in exec_module
  File "<frozen importlib._bootstrap>", line 241, in _call_with_frames_removed
  File "foodaApp/wsgi.py", line 12, in <module>
    from django.core.wsgi import get_wsgi_application
ModuleNotFoundError: No module named 'django'
Traceback (most recent call last):
  File "/home/poppymi2/public_html/app_food/passenger_wsgi.py", line 8, in <module>
    wsgi = imp.load_source('wsgi', 'foodaApp/wsgi.py')
           ^^^^^^^^^^^^^^^^^^^^^^^^^^^^^^^^^^^^^^^^^^^
  File "/opt/alt/python311/lib64/python3.11/imp.py", line 172, in load_source
    module = _load(spec)
             ^^^^^^^^^^^
  File "<frozen importlib._bootstrap>", line 721, in _load
  File "<frozen importlib._bootstrap>", line 690, in _load_unlocked
  File "<frozen importlib._bootstrap_external>", line 940, in exec_module
  File "<frozen importlib._bootstrap>", line 241, in _call_with_frames_removed
  File "foodaApp/wsgi.py", line 12, in <module>
    from django.core.wsgi import get_wsgi_application
ModuleNotFoundError: No module named 'django'
[UID:1745][3012777] Child process with pid: 3012784 was killed by signal: 15, core dumped: no
Traceback (most recent call last):
  File "/home/poppymi2/public_html/app_food/passenger_wsgi.py", line 8, in <module>
    wsgi = imp.load_source('wsgi', 'foodaApp/wsgi.py')
           ^^^^^^^^^^^^^^^^^^^^^^^^^^^^^^^^^^^^^^^^^^^
  File "/opt/alt/python311/lib64/python3.11/imp.py", line 172, in load_source
    module = _load(spec)
             ^^^^^^^^^^^
  File "<frozen importlib._bootstrap>", line 721, in _load
  File "<frozen importlib._bootstrap>", line 690, in _load_unlocked
  File "<frozen importlib._bootstrap_external>", line 940, in exec_module
  File "<frozen importlib._bootstrap>", line 241, in _call_with_frames_removed
  File "foodaApp/wsgi.py", line 12, in <module>
    from django.core.wsgi import get_wsgi_application
ModuleNotFoundError: No module named 'django'
Traceback (most recent call last):
  File "/home/poppymi2/public_html/app_food/passenger_wsgi.py", line 8, in <module>
    wsgi = imp.load_source('wsgi', 'foodaApp/wsgi.py')
           ^^^^^^^^^^^^^^^^^^^^^^^^^^^^^^^^^^^^^^^^^^^
  File "/opt/alt/python311/lib64/python3.11/imp.py", line 172, in load_source
    module = _load(spec)
             ^^^^^^^^^^^
  File "<frozen importlib._bootstrap>", line 721, in _load
  File "<frozen importlib._bootstrap>", line 690, in _load_unlocked
  File "<frozen importlib._bootstrap_external>", line 940, in exec_module
  File "<frozen importlib._bootstrap>", line 241, in _call_with_frames_removed
  File "foodaApp/wsgi.py", line 12, in <module>
    from django.core.wsgi import get_wsgi_application
ModuleNotFoundError: No module named 'django'
[UID:1745][3059226] Child process with pid: 3059231 was killed by signal: 15, core dumped: no
Traceback (most recent call last):
  File "/home/poppymi2/public_html/app_food/passenger_wsgi.py", line 8, in <module>
    wsgi = imp.load_source('wsgi', 'foodaApp/wsgi.py')
           ^^^^^^^^^^^^^^^^^^^^^^^^^^^^^^^^^^^^^^^^^^^
  File "/opt/alt/python311/lib64/python3.11/imp.py", line 172, in load_source
    module = _load(spec)
             ^^^^^^^^^^^
  File "<frozen importlib._bootstrap>", line 721, in _load
  File "<frozen importlib._bootstrap>", line 690, in _load_unlocked
  File "<frozen importlib._bootstrap_external>", line 940, in exec_module
  File "<frozen importlib._bootstrap>", line 241, in _call_with_frames_removed
  File "foodaApp/wsgi.py", line 12, in <module>
    from django.core.wsgi import get_wsgi_application
ModuleNotFoundError: No module named 'django'
[UID:1745][3059226] Child process with pid: 3059262 was killed by signal: 15, core dumped: no
Traceback (most recent call last):
  File "/home/poppymi2/public_html/app_food/passenger_wsgi.py", line 8, in <module>
    wsgi = imp.load_source('wsgi', 'foodaApp/wsgi.py')
           ^^^^^^^^^^^^^^^^^^^^^^^^^^^^^^^^^^^^^^^^^^^
  File "/opt/alt/python311/lib64/python3.11/imp.py", line 172, in load_source
    module = _load(spec)
             ^^^^^^^^^^^
  File "<frozen importlib._bootstrap>", line 721, in _load
  File "<frozen importlib._bootstrap>", line 690, in _load_unlocked
  File "<frozen importlib._bootstrap_external>", line 940, in exec_module
  File "<frozen importlib._bootstrap>", line 241, in _call_with_frames_removed
  File "foodaApp/wsgi.py", line 12, in <module>
    from django.core.wsgi import get_wsgi_application
ModuleNotFoundError: No module named 'django'
Traceback (most recent call last):
  File "/home/poppymi2/public_html/app_food/passenger_wsgi.py", line 8, in <module>
    wsgi = imp.load_source('wsgi', 'foodaApp/wsgi.py')
           ^^^^^^^^^^^^^^^^^^^^^^^^^^^^^^^^^^^^^^^^^^^
  File "/opt/alt/python311/lib64/python3.11/imp.py", line 172, in load_source
    module = _load(spec)
             ^^^^^^^^^^^
  File "<frozen importlib._bootstrap>", line 721, in _load
  File "<frozen importlib._bootstrap>", line 690, in _load_unlocked
  File "<frozen importlib._bootstrap_external>", line 940, in exec_module
  File "<frozen importlib._bootstrap>", line 241, in _call_with_frames_removed
  File "foodaApp/wsgi.py", line 12, in <module>
    from django.core.wsgi import get_wsgi_application
ModuleNotFoundError: No module named 'django'
[UID:1745][3061100] Child process with pid: 3061104 was killed by signal: 15, core dumped: no
Traceback (most recent call last):
  File "/home/poppymi2/public_html/app_food/passenger_wsgi.py", line 8, in <module>
    wsgi = imp.load_source('wsgi', 'foodaApp/wsgi.py')
           ^^^^^^^^^^^^^^^^^^^^^^^^^^^^^^^^^^^^^^^^^^^
  File "/opt/alt/python311/lib64/python3.11/imp.py", line 172, in load_source
    module = _load(spec)
             ^^^^^^^^^^^
  File "<frozen importlib._bootstrap>", line 721, in _load
  File "<frozen importlib._bootstrap>", line 690, in _load_unlocked
  File "<frozen importlib._bootstrap_external>", line 940, in exec_module
  File "<frozen importlib._bootstrap>", line 241, in _call_with_frames_removed
  File "foodaApp/wsgi.py", line 12, in <module>
    from django.core.wsgi import get_wsgi_application
ModuleNotFoundError: No module named 'django'
[UID:1745][3061100] Child process with pid: 3061142 was killed by signal: 15, core dumped: no
Traceback (most recent call last):
  File "/home/poppymi2/public_html/app_food/passenger_wsgi.py", line 8, in <module>
    wsgi = imp.load_source('wsgi', 'foodaApp/wsgi.py')
           ^^^^^^^^^^^^^^^^^^^^^^^^^^^^^^^^^^^^^^^^^^^
  File "/opt/alt/python311/lib64/python3.11/imp.py", line 172, in load_source
    module = _load(spec)
             ^^^^^^^^^^^
  File "<frozen importlib._bootstrap>", line 721, in _load
  File "<frozen importlib._bootstrap>", line 690, in _load_unlocked
  File "<frozen importlib._bootstrap_external>", line 940, in exec_module
  File "<frozen importlib._bootstrap>", line 241, in _call_with_frames_removed
  File "foodaApp/wsgi.py", line 12, in <module>
    from django.core.wsgi import get_wsgi_application
ModuleNotFoundError: No module named 'django'
[UID:1745][3061100] Child process with pid: 3061168 was killed by signal: 15, core dumped: no
Traceback (most recent call last):
  File "/home/poppymi2/public_html/app_food/passenger_wsgi.py", line 8, in <module>
    wsgi = imp.load_source('wsgi', 'foodaApp/wsgi.py')
           ^^^^^^^^^^^^^^^^^^^^^^^^^^^^^^^^^^^^^^^^^^^
  File "/opt/alt/python311/lib64/python3.11/imp.py", line 172, in load_source
    module = _load(spec)
             ^^^^^^^^^^^
  File "<frozen importlib._bootstrap>", line 721, in _load
  File "<frozen importlib._bootstrap>", line 690, in _load_unlocked
  File "<frozen importlib._bootstrap_external>", line 940, in exec_module
  File "<frozen importlib._bootstrap>", line 241, in _call_with_frames_removed
  File "foodaApp/wsgi.py", line 12, in <module>
    from django.core.wsgi import get_wsgi_application
ModuleNotFoundError: No module named 'django'
[UID:1745][3061100] Child process with pid: 3064829 was killed by signal: 15, core dumped: no
Traceback (most recent call last):
  File "/home/poppymi2/public_html/app_food/passenger_wsgi.py", line 8, in <module>
    wsgi = imp.load_source('wsgi', 'foodaApp/wsgi.py')
           ^^^^^^^^^^^^^^^^^^^^^^^^^^^^^^^^^^^^^^^^^^^
  File "/opt/alt/python311/lib64/python3.11/imp.py", line 172, in load_source
    module = _load(spec)
             ^^^^^^^^^^^
  File "<frozen importlib._bootstrap>", line 721, in _load
  File "<frozen importlib._bootstrap>", line 690, in _load_unlocked
  File "<frozen importlib._bootstrap_external>", line 940, in exec_module
  File "<frozen importlib._bootstrap>", line 241, in _call_with_frames_removed
  File "foodaApp/wsgi.py", line 12, in <module>
    from django.core.wsgi import get_wsgi_application
ModuleNotFoundError: No module named 'django'
[UID:1745][3061100] Child process with pid: 3064864 was killed by signal: 15, core dumped: no
Traceback (most recent call last):
  File "/home/poppymi2/public_html/app_food/passenger_wsgi.py", line 8, in <module>
    wsgi = imp.load_source('wsgi', 'foodaApp/wsgi.py')
           ^^^^^^^^^^^^^^^^^^^^^^^^^^^^^^^^^^^^^^^^^^^
  File "/opt/alt/python311/lib64/python3.11/imp.py", line 172, in load_source
    module = _load(spec)
             ^^^^^^^^^^^
  File "<frozen importlib._bootstrap>", line 721, in _load
  File "<frozen importlib._bootstrap>", line 690, in _load_unlocked
  File "<frozen importlib._bootstrap_external>", line 940, in exec_module
  File "<frozen importlib._bootstrap>", line 241, in _call_with_frames_removed
  File "foodaApp/wsgi.py", line 16, in <module>
    application = get_wsgi_application()
                  ^^^^^^^^^^^^^^^^^^^^^^
  File "/home/poppymi2/virtualenv/public_html/app_food/3.11/lib/python3.11/site-packages/django/core/wsgi.py", line 12, in get_wsgi_application
    django.setup(set_prefix=False)
  File "/home/poppymi2/virtualenv/public_html/app_food/3.11/lib/python3.11/site-packages/django/__init__.py", line 19, in setup
    configure_logging(settings.LOGGING_CONFIG, settings.LOGGING)
                      ^^^^^^^^^^^^^^^^^^^^^^^
  File "/home/poppymi2/virtualenv/public_html/app_food/3.11/lib/python3.11/site-packages/django/conf/__init__.py", line 89, in __getattr__
    self._setup(name)
  File "/home/poppymi2/virtualenv/public_html/app_food/3.11/lib/python3.11/site-packages/django/conf/__init__.py", line 76, in _setup
    self._wrapped = Settings(settings_module)
                    ^^^^^^^^^^^^^^^^^^^^^^^^^
  File "/home/poppymi2/virtualenv/public_html/app_food/3.11/lib/python3.11/site-packages/django/conf/__init__.py", line 190, in __init__
    mod = importlib.import_module(self.SETTINGS_MODULE)
          ^^^^^^^^^^^^^^^^^^^^^^^^^^^^^^^^^^^^^^^^^^^^^
  File "/opt/alt/python311/lib64/python3.11/importlib/__init__.py", line 126, in import_module
    return _bootstrap._gcd_import(name[level:], package, level)
           ^^^^^^^^^^^^^^^^^^^^^^^^^^^^^^^^^^^^^^^^^^^^^^^^^^^^
  File "<frozen importlib._bootstrap>", line 1204, in _gcd_import
  File "<frozen importlib._bootstrap>", line 1176, in _find_and_load
  File "<frozen importlib._bootstrap>", line 1147, in _find_and_load_unlocked
  File "<frozen importlib._bootstrap>", line 690, in _load_unlocked
  File "<frozen importlib._bootstrap_external>", line 940, in exec_module
  File "<frozen importlib._bootstrap>", line 241, in _call_with_frames_removed
  File "/home/poppymi2/public_html/app_food/foodaApp/settings.py", line 15, in <module>
    import pymysql
ModuleNotFoundError: No module named 'pymysql'
Traceback (most recent call last):
  File "/home/poppymi2/public_html/app_food/passenger_wsgi.py", line 8, in <module>
    wsgi = imp.load_source('wsgi', 'foodaApp/wsgi.py')
           ^^^^^^^^^^^^^^^^^^^^^^^^^^^^^^^^^^^^^^^^^^^
  File "/opt/alt/python311/lib64/python3.11/imp.py", line 172, in load_source
    module = _load(spec)
             ^^^^^^^^^^^
  File "<frozen importlib._bootstrap>", line 721, in _load
  File "<frozen importlib._bootstrap>", line 690, in _load_unlocked
  File "<frozen importlib._bootstrap_external>", line 940, in exec_module
  File "<frozen importlib._bootstrap>", line 241, in _call_with_frames_removed
  File "foodaApp/wsgi.py", line 16, in <module>
    application = get_wsgi_application()
                  ^^^^^^^^^^^^^^^^^^^^^^
  File "/home/poppymi2/virtualenv/public_html/app_food/3.11/lib/python3.11/site-packages/django/core/wsgi.py", line 12, in get_wsgi_application
    django.setup(set_prefix=False)
  File "/home/poppymi2/virtualenv/public_html/app_food/3.11/lib/python3.11/site-packages/django/__init__.py", line 19, in setup
    configure_logging(settings.LOGGING_CONFIG, settings.LOGGING)
                      ^^^^^^^^^^^^^^^^^^^^^^^
  File "/home/poppymi2/virtualenv/public_html/app_food/3.11/lib/python3.11/site-packages/django/conf/__init__.py", line 89, in __getattr__
    self._setup(name)
  File "/home/poppymi2/virtualenv/public_html/app_food/3.11/lib/python3.11/site-packages/django/conf/__init__.py", line 76, in _setup
    self._wrapped = Settings(settings_module)
                    ^^^^^^^^^^^^^^^^^^^^^^^^^
  File "/home/poppymi2/virtualenv/public_html/app_food/3.11/lib/python3.11/site-packages/django/conf/__init__.py", line 190, in __init__
    mod = importlib.import_module(self.SETTINGS_MODULE)
          ^^^^^^^^^^^^^^^^^^^^^^^^^^^^^^^^^^^^^^^^^^^^^
  File "/opt/alt/python311/lib64/python3.11/importlib/__init__.py", line 126, in import_module
    return _bootstrap._gcd_import(name[level:], package, level)
           ^^^^^^^^^^^^^^^^^^^^^^^^^^^^^^^^^^^^^^^^^^^^^^^^^^^^
  File "<frozen importlib._bootstrap>", line 1204, in _gcd_import
  File "<frozen importlib._bootstrap>", line 1176, in _find_and_load
  File "<frozen importlib._bootstrap>", line 1147, in _find_and_load_unlocked
  File "<frozen importlib._bootstrap>", line 690, in _load_unlocked
  File "<frozen importlib._bootstrap_external>", line 940, in exec_module
  File "<frozen importlib._bootstrap>", line 241, in _call_with_frames_removed
  File "/home/poppymi2/public_html/app_food/foodaApp/settings.py", line 15, in <module>
    import pymysql
ModuleNotFoundError: No module named 'pymysql'
[UID:1745][3084374] Child process with pid: 3084417 was killed by signal: 15, core dumped: no
Traceback (most recent call last):
  File "/home/poppymi2/public_html/app_food/passenger_wsgi.py", line 8, in <module>
    wsgi = imp.load_source('wsgi', 'foodaApp/wsgi.py')
           ^^^^^^^^^^^^^^^^^^^^^^^^^^^^^^^^^^^^^^^^^^^
  File "/opt/alt/python311/lib64/python3.11/imp.py", line 172, in load_source
    module = _load(spec)
             ^^^^^^^^^^^
  File "<frozen importlib._bootstrap>", line 721, in _load
  File "<frozen importlib._bootstrap>", line 690, in _load_unlocked
  File "<frozen importlib._bootstrap_external>", line 940, in exec_module
  File "<frozen importlib._bootstrap>", line 241, in _call_with_frames_removed
  File "foodaApp/wsgi.py", line 16, in <module>
    application = get_wsgi_application()
                  ^^^^^^^^^^^^^^^^^^^^^^
  File "/home/poppymi2/virtualenv/public_html/app_food/3.11/lib/python3.11/site-packages/django/core/wsgi.py", line 12, in get_wsgi_application
    django.setup(set_prefix=False)
  File "/home/poppymi2/virtualenv/public_html/app_food/3.11/lib/python3.11/site-packages/django/__init__.py", line 19, in setup
    configure_logging(settings.LOGGING_CONFIG, settings.LOGGING)
                      ^^^^^^^^^^^^^^^^^^^^^^^
  File "/home/poppymi2/virtualenv/public_html/app_food/3.11/lib/python3.11/site-packages/django/conf/__init__.py", line 89, in __getattr__
    self._setup(name)
  File "/home/poppymi2/virtualenv/public_html/app_food/3.11/lib/python3.11/site-packages/django/conf/__init__.py", line 76, in _setup
    self._wrapped = Settings(settings_module)
                    ^^^^^^^^^^^^^^^^^^^^^^^^^
  File "/home/poppymi2/virtualenv/public_html/app_food/3.11/lib/python3.11/site-packages/django/conf/__init__.py", line 190, in __init__
    mod = importlib.import_module(self.SETTINGS_MODULE)
          ^^^^^^^^^^^^^^^^^^^^^^^^^^^^^^^^^^^^^^^^^^^^^
  File "/opt/alt/python311/lib64/python3.11/importlib/__init__.py", line 126, in import_module
    return _bootstrap._gcd_import(name[level:], package, level)
           ^^^^^^^^^^^^^^^^^^^^^^^^^^^^^^^^^^^^^^^^^^^^^^^^^^^^
  File "<frozen importlib._bootstrap>", line 1204, in _gcd_import
  File "<frozen importlib._bootstrap>", line 1176, in _find_and_load
  File "<frozen importlib._bootstrap>", line 1147, in _find_and_load_unlocked
  File "<frozen importlib._bootstrap>", line 690, in _load_unlocked
  File "<frozen importlib._bootstrap_external>", line 940, in exec_module
  File "<frozen importlib._bootstrap>", line 241, in _call_with_frames_removed
  File "/home/poppymi2/public_html/app_food/foodaApp/settings.py", line 15, in <module>
    import pymysql
ModuleNotFoundError: No module named 'pymysql'
Traceback (most recent call last):
  File "/home/poppymi2/public_html/app_food/passenger_wsgi.py", line 8, in <module>
    wsgi = imp.load_source('wsgi', 'foodaApp/wsgi.py')
           ^^^^^^^^^^^^^^^^^^^^^^^^^^^^^^^^^^^^^^^^^^^
  File "/opt/alt/python311/lib64/python3.11/imp.py", line 172, in load_source
    module = _load(spec)
             ^^^^^^^^^^^
  File "<frozen importlib._bootstrap>", line 721, in _load
  File "<frozen importlib._bootstrap>", line 690, in _load_unlocked
  File "<frozen importlib._bootstrap_external>", line 940, in exec_module
  File "<frozen importlib._bootstrap>", line 241, in _call_with_frames_removed
  File "foodaApp/wsgi.py", line 16, in <module>
    application = get_wsgi_application()
                  ^^^^^^^^^^^^^^^^^^^^^^
  File "/home/poppymi2/virtualenv/public_html/app_food/3.11/lib/python3.11/site-packages/django/core/wsgi.py", line 12, in get_wsgi_application
    django.setup(set_prefix=False)
  File "/home/poppymi2/virtualenv/public_html/app_food/3.11/lib/python3.11/site-packages/django/__init__.py", line 19, in setup
    configure_logging(settings.LOGGING_CONFIG, settings.LOGGING)
                      ^^^^^^^^^^^^^^^^^^^^^^^
  File "/home/poppymi2/virtualenv/public_html/app_food/3.11/lib/python3.11/site-packages/django/conf/__init__.py", line 89, in __getattr__
    self._setup(name)
  File "/home/poppymi2/virtualenv/public_html/app_food/3.11/lib/python3.11/site-packages/django/conf/__init__.py", line 76, in _setup
    self._wrapped = Settings(settings_module)
                    ^^^^^^^^^^^^^^^^^^^^^^^^^
  File "/home/poppymi2/virtualenv/public_html/app_food/3.11/lib/python3.11/site-packages/django/conf/__init__.py", line 190, in __init__
    mod = importlib.import_module(self.SETTINGS_MODULE)
          ^^^^^^^^^^^^^^^^^^^^^^^^^^^^^^^^^^^^^^^^^^^^^
  File "/opt/alt/python311/lib64/python3.11/importlib/__init__.py", line 126, in import_module
    return _bootstrap._gcd_import(name[level:], package, level)
           ^^^^^^^^^^^^^^^^^^^^^^^^^^^^^^^^^^^^^^^^^^^^^^^^^^^^
  File "<frozen importlib._bootstrap>", line 1204, in _gcd_import
  File "<frozen importlib._bootstrap>", line 1176, in _find_and_load
  File "<frozen importlib._bootstrap>", line 1147, in _find_and_load_unlocked
  File "<frozen importlib._bootstrap>", line 690, in _load_unlocked
  File "<frozen importlib._bootstrap_external>", line 940, in exec_module
  File "<frozen importlib._bootstrap>", line 241, in _call_with_frames_removed
  File "/home/poppymi2/public_html/app_food/foodaApp/settings.py", line 15, in <module>
    import pymysql
ModuleNotFoundError: No module named 'pymysql'
[UID:1745][3085984] Child process with pid: 3085991 was killed by signal: 15, core dumped: no
Traceback (most recent call last):
  File "/home/poppymi2/public_html/app_food/passenger_wsgi.py", line 8, in <module>
    wsgi = imp.load_source('wsgi', 'foodaApp/wsgi.py')
           ^^^^^^^^^^^^^^^^^^^^^^^^^^^^^^^^^^^^^^^^^^^
  File "/opt/alt/python311/lib64/python3.11/imp.py", line 172, in load_source
    module = _load(spec)
             ^^^^^^^^^^^
  File "<frozen importlib._bootstrap>", line 721, in _load
  File "<frozen importlib._bootstrap>", line 690, in _load_unlocked
  File "<frozen importlib._bootstrap_external>", line 940, in exec_module
  File "<frozen importlib._bootstrap>", line 241, in _call_with_frames_removed
  File "foodaApp/wsgi.py", line 16, in <module>
    application = get_wsgi_application()
                  ^^^^^^^^^^^^^^^^^^^^^^
  File "/home/poppymi2/virtualenv/public_html/app_food/3.11/lib/python3.11/site-packages/django/core/wsgi.py", line 12, in get_wsgi_application
    django.setup(set_prefix=False)
  File "/home/poppymi2/virtualenv/public_html/app_food/3.11/lib/python3.11/site-packages/django/__init__.py", line 19, in setup
    configure_logging(settings.LOGGING_CONFIG, settings.LOGGING)
                      ^^^^^^^^^^^^^^^^^^^^^^^
  File "/home/poppymi2/virtualenv/public_html/app_food/3.11/lib/python3.11/site-packages/django/conf/__init__.py", line 89, in __getattr__
    self._setup(name)
  File "/home/poppymi2/virtualenv/public_html/app_food/3.11/lib/python3.11/site-packages/django/conf/__init__.py", line 76, in _setup
    self._wrapped = Settings(settings_module)
                    ^^^^^^^^^^^^^^^^^^^^^^^^^
  File "/home/poppymi2/virtualenv/public_html/app_food/3.11/lib/python3.11/site-packages/django/conf/__init__.py", line 190, in __init__
    mod = importlib.import_module(self.SETTINGS_MODULE)
          ^^^^^^^^^^^^^^^^^^^^^^^^^^^^^^^^^^^^^^^^^^^^^
  File "/opt/alt/python311/lib64/python3.11/importlib/__init__.py", line 126, in import_module
    return _bootstrap._gcd_import(name[level:], package, level)
           ^^^^^^^^^^^^^^^^^^^^^^^^^^^^^^^^^^^^^^^^^^^^^^^^^^^^
  File "<frozen importlib._bootstrap>", line 1204, in _gcd_import
  File "<frozen importlib._bootstrap>", line 1176, in _find_and_load
  File "<frozen importlib._bootstrap>", line 1147, in _find_and_load_unlocked
  File "<frozen importlib._bootstrap>", line 690, in _load_unlocked
  File "<frozen importlib._bootstrap_external>", line 940, in exec_module
  File "<frozen importlib._bootstrap>", line 241, in _call_with_frames_removed
  File "/home/poppymi2/public_html/app_food/foodaApp/settings.py", line 15, in <module>
    import pymysql
ModuleNotFoundError: No module named 'pymysql'
[UID:1745][3085984] Child process with pid: 3086023 was killed by signal: 15, core dumped: no
Traceback (most recent call last):
  File "/home/poppymi2/public_html/app_food/passenger_wsgi.py", line 8, in <module>
    wsgi = imp.load_source('wsgi', 'foodaApp/wsgi.py')
           ^^^^^^^^^^^^^^^^^^^^^^^^^^^^^^^^^^^^^^^^^^^
  File "/opt/alt/python311/lib64/python3.11/imp.py", line 172, in load_source
    module = _load(spec)
             ^^^^^^^^^^^
  File "<frozen importlib._bootstrap>", line 721, in _load
  File "<frozen importlib._bootstrap>", line 690, in _load_unlocked
  File "<frozen importlib._bootstrap_external>", line 940, in exec_module
  File "<frozen importlib._bootstrap>", line 241, in _call_with_frames_removed
  File "foodaApp/wsgi.py", line 16, in <module>
    application = get_wsgi_application()
                  ^^^^^^^^^^^^^^^^^^^^^^
  File "/home/poppymi2/virtualenv/public_html/app_food/3.11/lib/python3.11/site-packages/django/core/wsgi.py", line 12, in get_wsgi_application
    django.setup(set_prefix=False)
  File "/home/poppymi2/virtualenv/public_html/app_food/3.11/lib/python3.11/site-packages/django/__init__.py", line 24, in setup
    apps.populate(settings.INSTALLED_APPS)
  File "/home/poppymi2/virtualenv/public_html/app_food/3.11/lib/python3.11/site-packages/django/apps/registry.py", line 91, in populate
    app_config = AppConfig.create(entry)
                 ^^^^^^^^^^^^^^^^^^^^^^^
  File "/home/poppymi2/virtualenv/public_html/app_food/3.11/lib/python3.11/site-packages/django/apps/config.py", line 193, in create
    import_module(entry)
  File "/opt/alt/python311/lib64/python3.11/importlib/__init__.py", line 126, in import_module
    return _bootstrap._gcd_import(name[level:], package, level)
           ^^^^^^^^^^^^^^^^^^^^^^^^^^^^^^^^^^^^^^^^^^^^^^^^^^^^
  File "<frozen importlib._bootstrap>", line 1204, in _gcd_import
  File "<frozen importlib._bootstrap>", line 1176, in _find_and_load
  File "<frozen importlib._bootstrap>", line 1140, in _find_and_load_unlocked
ModuleNotFoundError: No module named 'admin_interface'
Traceback (most recent call last):
  File "/home/poppymi2/public_html/app_food/passenger_wsgi.py", line 8, in <module>
    wsgi = imp.load_source('wsgi', 'foodaApp/wsgi.py')
           ^^^^^^^^^^^^^^^^^^^^^^^^^^^^^^^^^^^^^^^^^^^
  File "/opt/alt/python311/lib64/python3.11/imp.py", line 172, in load_source
    module = _load(spec)
             ^^^^^^^^^^^
  File "<frozen importlib._bootstrap>", line 721, in _load
  File "<frozen importlib._bootstrap>", line 690, in _load_unlocked
  File "<frozen importlib._bootstrap_external>", line 940, in exec_module
  File "<frozen importlib._bootstrap>", line 241, in _call_with_frames_removed
  File "foodaApp/wsgi.py", line 16, in <module>
    application = get_wsgi_application()
                  ^^^^^^^^^^^^^^^^^^^^^^
  File "/home/poppymi2/virtualenv/public_html/app_food/3.11/lib/python3.11/site-packages/django/core/wsgi.py", line 12, in get_wsgi_application
    django.setup(set_prefix=False)
  File "/home/poppymi2/virtualenv/public_html/app_food/3.11/lib/python3.11/site-packages/django/__init__.py", line 24, in setup
    apps.populate(settings.INSTALLED_APPS)
  File "/home/poppymi2/virtualenv/public_html/app_food/3.11/lib/python3.11/site-packages/django/apps/registry.py", line 83, in populate
    raise RuntimeError("populate() isn't reentrant")
RuntimeError: populate() isn't reentrant
[UID:1745][3118460] Child process with pid: 3118472 was killed by signal: 15, core dumped: no
Traceback (most recent call last):
  File "/home/poppymi2/public_html/app_food/passenger_wsgi.py", line 8, in <module>
    wsgi = imp.load_source('wsgi', 'foodaApp/wsgi.py')
           ^^^^^^^^^^^^^^^^^^^^^^^^^^^^^^^^^^^^^^^^^^^
  File "/opt/alt/python311/lib64/python3.11/imp.py", line 172, in load_source
    module = _load(spec)
             ^^^^^^^^^^^
  File "<frozen importlib._bootstrap>", line 721, in _load
  File "<frozen importlib._bootstrap>", line 690, in _load_unlocked
  File "<frozen importlib._bootstrap_external>", line 940, in exec_module
  File "<frozen importlib._bootstrap>", line 241, in _call_with_frames_removed
  File "foodaApp/wsgi.py", line 16, in <module>
    application = get_wsgi_application()
                  ^^^^^^^^^^^^^^^^^^^^^^
  File "/home/poppymi2/virtualenv/public_html/app_food/3.11/lib/python3.11/site-packages/django/core/wsgi.py", line 12, in get_wsgi_application
    django.setup(set_prefix=False)
  File "/home/poppymi2/virtualenv/public_html/app_food/3.11/lib/python3.11/site-packages/django/__init__.py", line 24, in setup
    apps.populate(settings.INSTALLED_APPS)
  File "/home/poppymi2/virtualenv/public_html/app_food/3.11/lib/python3.11/site-packages/django/apps/registry.py", line 91, in populate
    app_config = AppConfig.create(entry)
                 ^^^^^^^^^^^^^^^^^^^^^^^
  File "/home/poppymi2/virtualenv/public_html/app_food/3.11/lib/python3.11/site-packages/django/apps/config.py", line 193, in create
    import_module(entry)
  File "/opt/alt/python311/lib64/python3.11/importlib/__init__.py", line 126, in import_module
    return _bootstrap._gcd_import(name[level:], package, level)
           ^^^^^^^^^^^^^^^^^^^^^^^^^^^^^^^^^^^^^^^^^^^^^^^^^^^^
  File "<frozen importlib._bootstrap>", line 1204, in _gcd_import
  File "<frozen importlib._bootstrap>", line 1176, in _find_and_load
  File "<frozen importlib._bootstrap>", line 1140, in _find_and_load_unlocked
ModuleNotFoundError: No module named 'admin_interface'
Traceback (most recent call last):
  File "/home/poppymi2/public_html/app_food/passenger_wsgi.py", line 8, in <module>
    wsgi = imp.load_source('wsgi', 'foodaApp/wsgi.py')
           ^^^^^^^^^^^^^^^^^^^^^^^^^^^^^^^^^^^^^^^^^^^
  File "/opt/alt/python311/lib64/python3.11/imp.py", line 172, in load_source
    module = _load(spec)
             ^^^^^^^^^^^
  File "<frozen importlib._bootstrap>", line 721, in _load
  File "<frozen importlib._bootstrap>", line 690, in _load_unlocked
  File "<frozen importlib._bootstrap_external>", line 940, in exec_module
  File "<frozen importlib._bootstrap>", line 241, in _call_with_frames_removed
  File "foodaApp/wsgi.py", line 16, in <module>
    application = get_wsgi_application()
                  ^^^^^^^^^^^^^^^^^^^^^^
  File "/home/poppymi2/virtualenv/public_html/app_food/3.11/lib/python3.11/site-packages/django/core/wsgi.py", line 12, in get_wsgi_application
    django.setup(set_prefix=False)
  File "/home/poppymi2/virtualenv/public_html/app_food/3.11/lib/python3.11/site-packages/django/__init__.py", line 24, in setup
    apps.populate(settings.INSTALLED_APPS)
  File "/home/poppymi2/virtualenv/public_html/app_food/3.11/lib/python3.11/site-packages/django/apps/registry.py", line 83, in populate
    raise RuntimeError("populate() isn't reentrant")
RuntimeError: populate() isn't reentrant
[UID:1745][3121493] Child process with pid: 3121497 was killed by signal: 15, core dumped: no
Traceback (most recent call last):
  File "/home/poppymi2/public_html/app_food/passenger_wsgi.py", line 8, in <module>
    wsgi = imp.load_source('wsgi', 'foodaApp/wsgi.py')
           ^^^^^^^^^^^^^^^^^^^^^^^^^^^^^^^^^^^^^^^^^^^
  File "/opt/alt/python311/lib64/python3.11/imp.py", line 172, in load_source
    module = _load(spec)
             ^^^^^^^^^^^
  File "<frozen importlib._bootstrap>", line 721, in _load
  File "<frozen importlib._bootstrap>", line 690, in _load_unlocked
  File "<frozen importlib._bootstrap_external>", line 940, in exec_module
  File "<frozen importlib._bootstrap>", line 241, in _call_with_frames_removed
  File "foodaApp/wsgi.py", line 16, in <module>
    application = get_wsgi_application()
                  ^^^^^^^^^^^^^^^^^^^^^^
  File "/home/poppymi2/virtualenv/public_html/app_food/3.11/lib/python3.11/site-packages/django/core/wsgi.py", line 12, in get_wsgi_application
    django.setup(set_prefix=False)
  File "/home/poppymi2/virtualenv/public_html/app_food/3.11/lib/python3.11/site-packages/django/__init__.py", line 24, in setup
    apps.populate(settings.INSTALLED_APPS)
  File "/home/poppymi2/virtualenv/public_html/app_food/3.11/lib/python3.11/site-packages/django/apps/registry.py", line 91, in populate
    app_config = AppConfig.create(entry)
                 ^^^^^^^^^^^^^^^^^^^^^^^
  File "/home/poppymi2/virtualenv/public_html/app_food/3.11/lib/python3.11/site-packages/django/apps/config.py", line 193, in create
    import_module(entry)
  File "/opt/alt/python311/lib64/python3.11/importlib/__init__.py", line 126, in import_module
    return _bootstrap._gcd_import(name[level:], package, level)
           ^^^^^^^^^^^^^^^^^^^^^^^^^^^^^^^^^^^^^^^^^^^^^^^^^^^^
  File "<frozen importlib._bootstrap>", line 1204, in _gcd_import
  File "<frozen importlib._bootstrap>", line 1176, in _find_and_load
  File "<frozen importlib._bootstrap>", line 1140, in _find_and_load_unlocked
ModuleNotFoundError: No module named 'translation_manager'
Traceback (most recent call last):
  File "/home/poppymi2/public_html/app_food/passenger_wsgi.py", line 8, in <module>
    wsgi = imp.load_source('wsgi', 'foodaApp/wsgi.py')
           ^^^^^^^^^^^^^^^^^^^^^^^^^^^^^^^^^^^^^^^^^^^
  File "/opt/alt/python311/lib64/python3.11/imp.py", line 172, in load_source
    module = _load(spec)
             ^^^^^^^^^^^
  File "<frozen importlib._bootstrap>", line 721, in _load
  File "<frozen importlib._bootstrap>", line 690, in _load_unlocked
  File "<frozen importlib._bootstrap_external>", line 940, in exec_module
  File "<frozen importlib._bootstrap>", line 241, in _call_with_frames_removed
  File "foodaApp/wsgi.py", line 16, in <module>
    application = get_wsgi_application()
                  ^^^^^^^^^^^^^^^^^^^^^^
  File "/home/poppymi2/virtualenv/public_html/app_food/3.11/lib/python3.11/site-packages/django/core/wsgi.py", line 12, in get_wsgi_application
    django.setup(set_prefix=False)
  File "/home/poppymi2/virtualenv/public_html/app_food/3.11/lib/python3.11/site-packages/django/__init__.py", line 24, in setup
    apps.populate(settings.INSTALLED_APPS)
  File "/home/poppymi2/virtualenv/public_html/app_food/3.11/lib/python3.11/site-packages/django/apps/registry.py", line 83, in populate
    raise RuntimeError("populate() isn't reentrant")
RuntimeError: populate() isn't reentrant
[UID:1745][3145621] Child process with pid: 3145627 was killed by signal: 15, core dumped: no
Traceback (most recent call last):
  File "/home/poppymi2/public_html/app_food/passenger_wsgi.py", line 8, in <module>
    wsgi = imp.load_source('wsgi', 'foodaApp/wsgi.py')
           ^^^^^^^^^^^^^^^^^^^^^^^^^^^^^^^^^^^^^^^^^^^
  File "/opt/alt/python311/lib64/python3.11/imp.py", line 172, in load_source
    module = _load(spec)
             ^^^^^^^^^^^
  File "<frozen importlib._bootstrap>", line 721, in _load
  File "<frozen importlib._bootstrap>", line 690, in _load_unlocked
  File "<frozen importlib._bootstrap_external>", line 940, in exec_module
  File "<frozen importlib._bootstrap>", line 241, in _call_with_frames_removed
  File "foodaApp/wsgi.py", line 16, in <module>
    application = get_wsgi_application()
                  ^^^^^^^^^^^^^^^^^^^^^^
  File "/home/poppymi2/virtualenv/public_html/app_food/3.11/lib/python3.11/site-packages/django/core/wsgi.py", line 12, in get_wsgi_application
    django.setup(set_prefix=False)
  File "/home/poppymi2/virtualenv/public_html/app_food/3.11/lib/python3.11/site-packages/django/__init__.py", line 24, in setup
    apps.populate(settings.INSTALLED_APPS)
  File "/home/poppymi2/virtualenv/public_html/app_food/3.11/lib/python3.11/site-packages/django/apps/registry.py", line 91, in populate
    app_config = AppConfig.create(entry)
                 ^^^^^^^^^^^^^^^^^^^^^^^
  File "/home/poppymi2/virtualenv/public_html/app_food/3.11/lib/python3.11/site-packages/django/apps/config.py", line 193, in create
    import_module(entry)
  File "/opt/alt/python311/lib64/python3.11/importlib/__init__.py", line 126, in import_module
    return _bootstrap._gcd_import(name[level:], package, level)
           ^^^^^^^^^^^^^^^^^^^^^^^^^^^^^^^^^^^^^^^^^^^^^^^^^^^^
  File "<frozen importlib._bootstrap>", line 1204, in _gcd_import
  File "<frozen importlib._bootstrap>", line 1176, in _find_and_load
  File "<frozen importlib._bootstrap>", line 1140, in _find_and_load_unlocked
ModuleNotFoundError: No module named 'translation_manager'
Traceback (most recent call last):
  File "/home/poppymi2/public_html/app_food/passenger_wsgi.py", line 8, in <module>
    wsgi = imp.load_source('wsgi', 'foodaApp/wsgi.py')
           ^^^^^^^^^^^^^^^^^^^^^^^^^^^^^^^^^^^^^^^^^^^
  File "/opt/alt/python311/lib64/python3.11/imp.py", line 172, in load_source
    module = _load(spec)
             ^^^^^^^^^^^
  File "<frozen importlib._bootstrap>", line 721, in _load
  File "<frozen importlib._bootstrap>", line 690, in _load_unlocked
  File "<frozen importlib._bootstrap_external>", line 940, in exec_module
  File "<frozen importlib._bootstrap>", line 241, in _call_with_frames_removed
  File "foodaApp/wsgi.py", line 16, in <module>
    application = get_wsgi_application()
                  ^^^^^^^^^^^^^^^^^^^^^^
  File "/home/poppymi2/virtualenv/public_html/app_food/3.11/lib/python3.11/site-packages/django/core/wsgi.py", line 12, in get_wsgi_application
    django.setup(set_prefix=False)
  File "/home/poppymi2/virtualenv/public_html/app_food/3.11/lib/python3.11/site-packages/django/__init__.py", line 24, in setup
    apps.populate(settings.INSTALLED_APPS)
  File "/home/poppymi2/virtualenv/public_html/app_food/3.11/lib/python3.11/site-packages/django/apps/registry.py", line 83, in populate
    raise RuntimeError("populate() isn't reentrant")
RuntimeError: populate() isn't reentrant
[UID:1745][3145724] Child process with pid: 3145758 was killed by signal: 15, core dumped: no
Traceback (most recent call last):
  File "/home/poppymi2/public_html/app_food/passenger_wsgi.py", line 8, in <module>
    wsgi = imp.load_source('wsgi', 'foodaApp/wsgi.py')
           ^^^^^^^^^^^^^^^^^^^^^^^^^^^^^^^^^^^^^^^^^^^
  File "/opt/alt/python311/lib64/python3.11/imp.py", line 172, in load_source
    module = _load(spec)
             ^^^^^^^^^^^
  File "<frozen importlib._bootstrap>", line 721, in _load
  File "<frozen importlib._bootstrap>", line 690, in _load_unlocked
  File "<frozen importlib._bootstrap_external>", line 940, in exec_module
  File "<frozen importlib._bootstrap>", line 241, in _call_with_frames_removed
  File "foodaApp/wsgi.py", line 16, in <module>
    application = get_wsgi_application()
                  ^^^^^^^^^^^^^^^^^^^^^^
  File "/home/poppymi2/virtualenv/public_html/app_food/3.11/lib/python3.11/site-packages/django/core/wsgi.py", line 12, in get_wsgi_application
    django.setup(set_prefix=False)
  File "/home/poppymi2/virtualenv/public_html/app_food/3.11/lib/python3.11/site-packages/django/__init__.py", line 24, in setup
    apps.populate(settings.INSTALLED_APPS)
  File "/home/poppymi2/virtualenv/public_html/app_food/3.11/lib/python3.11/site-packages/django/apps/registry.py", line 83, in populate
    raise RuntimeError("populate() isn't reentrant")
RuntimeError: populate() isn't reentrant
[UID:1745][3145724] Child process with pid: 3147004 was killed by signal: 15, core dumped: no
Traceback (most recent call last):
  File "/home/poppymi2/public_html/app_food/passenger_wsgi.py", line 8, in <module>
    wsgi = imp.load_source('wsgi', 'foodaApp/wsgi.py')
           ^^^^^^^^^^^^^^^^^^^^^^^^^^^^^^^^^^^^^^^^^^^
  File "/opt/alt/python311/lib64/python3.11/imp.py", line 172, in load_source
    module = _load(spec)
             ^^^^^^^^^^^
  File "<frozen importlib._bootstrap>", line 721, in _load
  File "<frozen importlib._bootstrap>", line 690, in _load_unlocked
  File "<frozen importlib._bootstrap_external>", line 940, in exec_module
  File "<frozen importlib._bootstrap>", line 241, in _call_with_frames_removed
  File "foodaApp/wsgi.py", line 16, in <module>
    application = get_wsgi_application()
                  ^^^^^^^^^^^^^^^^^^^^^^
  File "/home/poppymi2/virtualenv/public_html/app_food/3.11/lib/python3.11/site-packages/django/core/wsgi.py", line 12, in get_wsgi_application
    django.setup(set_prefix=False)
  File "/home/poppymi2/virtualenv/public_html/app_food/3.11/lib/python3.11/site-packages/django/__init__.py", line 24, in setup
    apps.populate(settings.INSTALLED_APPS)
  File "/home/poppymi2/virtualenv/public_html/app_food/3.11/lib/python3.11/site-packages/django/apps/registry.py", line 91, in populate
    app_config = AppConfig.create(entry)
                 ^^^^^^^^^^^^^^^^^^^^^^^
  File "/home/poppymi2/virtualenv/public_html/app_food/3.11/lib/python3.11/site-packages/django/apps/config.py", line 193, in create
    import_module(entry)
  File "/opt/alt/python311/lib64/python3.11/importlib/__init__.py", line 126, in import_module
    return _bootstrap._gcd_import(name[level:], package, level)
           ^^^^^^^^^^^^^^^^^^^^^^^^^^^^^^^^^^^^^^^^^^^^^^^^^^^^
  File "<frozen importlib._bootstrap>", line 1204, in _gcd_import
  File "<frozen importlib._bootstrap>", line 1176, in _find_and_load
  File "<frozen importlib._bootstrap>", line 1140, in _find_and_load_unlocked
ModuleNotFoundError: No module named 'translation_manager'
Traceback (most recent call last):
  File "/home/poppymi2/public_html/app_food/passenger_wsgi.py", line 8, in <module>
    wsgi = imp.load_source('wsgi', 'foodaApp/wsgi.py')
           ^^^^^^^^^^^^^^^^^^^^^^^^^^^^^^^^^^^^^^^^^^^
  File "/opt/alt/python311/lib64/python3.11/imp.py", line 172, in load_source
    module = _load(spec)
             ^^^^^^^^^^^
  File "<frozen importlib._bootstrap>", line 721, in _load
  File "<frozen importlib._bootstrap>", line 690, in _load_unlocked
  File "<frozen importlib._bootstrap_external>", line 940, in exec_module
  File "<frozen importlib._bootstrap>", line 241, in _call_with_frames_removed
  File "foodaApp/wsgi.py", line 16, in <module>
    application = get_wsgi_application()
                  ^^^^^^^^^^^^^^^^^^^^^^
  File "/home/poppymi2/virtualenv/public_html/app_food/3.11/lib/python3.11/site-packages/django/core/wsgi.py", line 12, in get_wsgi_application
    django.setup(set_prefix=False)
  File "/home/poppymi2/virtualenv/public_html/app_food/3.11/lib/python3.11/site-packages/django/__init__.py", line 24, in setup
    apps.populate(settings.INSTALLED_APPS)
  File "/home/poppymi2/virtualenv/public_html/app_food/3.11/lib/python3.11/site-packages/django/apps/registry.py", line 83, in populate
    raise RuntimeError("populate() isn't reentrant")
RuntimeError: populate() isn't reentrant
[UID:1745][3158697] Child process with pid: 3158703 was killed by signal: 15, core dumped: no
Traceback (most recent call last):
  File "/home/poppymi2/public_html/app_food/passenger_wsgi.py", line 8, in <module>
    wsgi = imp.load_source('wsgi', 'foodaApp/wsgi.py')
           ^^^^^^^^^^^^^^^^^^^^^^^^^^^^^^^^^^^^^^^^^^^
  File "/opt/alt/python311/lib64/python3.11/imp.py", line 172, in load_source
    module = _load(spec)
             ^^^^^^^^^^^
  File "<frozen importlib._bootstrap>", line 721, in _load
  File "<frozen importlib._bootstrap>", line 690, in _load_unlocked
  File "<frozen importlib._bootstrap_external>", line 940, in exec_module
  File "<frozen importlib._bootstrap>", line 241, in _call_with_frames_removed
  File "foodaApp/wsgi.py", line 16, in <module>
    application = get_wsgi_application()
                  ^^^^^^^^^^^^^^^^^^^^^^
  File "/home/poppymi2/virtualenv/public_html/app_food/3.11/lib/python3.11/site-packages/django/core/wsgi.py", line 12, in get_wsgi_application
    django.setup(set_prefix=False)
  File "/home/poppymi2/virtualenv/public_html/app_food/3.11/lib/python3.11/site-packages/django/__init__.py", line 24, in setup
    apps.populate(settings.INSTALLED_APPS)
  File "/home/poppymi2/virtualenv/public_html/app_food/3.11/lib/python3.11/site-packages/django/apps/registry.py", line 83, in populate
    raise RuntimeError("populate() isn't reentrant")
RuntimeError: populate() isn't reentrant
[UID:1745][3158697] Child process with pid: 3158787 was killed by signal: 15, core dumped: no
Traceback (most recent call last):
  File "/home/poppymi2/public_html/app_food/passenger_wsgi.py", line 8, in <module>
    wsgi = imp.load_source('wsgi', 'foodaApp/wsgi.py')
           ^^^^^^^^^^^^^^^^^^^^^^^^^^^^^^^^^^^^^^^^^^^
  File "/opt/alt/python311/lib64/python3.11/imp.py", line 172, in load_source
    module = _load(spec)
             ^^^^^^^^^^^
  File "<frozen importlib._bootstrap>", line 721, in _load
  File "<frozen importlib._bootstrap>", line 690, in _load_unlocked
  File "<frozen importlib._bootstrap_external>", line 940, in exec_module
  File "<frozen importlib._bootstrap>", line 241, in _call_with_frames_removed
  File "foodaApp/wsgi.py", line 16, in <module>
    application = get_wsgi_application()
                  ^^^^^^^^^^^^^^^^^^^^^^
  File "/home/poppymi2/virtualenv/public_html/app_food/3.11/lib/python3.11/site-packages/django/core/wsgi.py", line 12, in get_wsgi_application
    django.setup(set_prefix=False)
  File "/home/poppymi2/virtualenv/public_html/app_food/3.11/lib/python3.11/site-packages/django/__init__.py", line 24, in setup
    apps.populate(settings.INSTALLED_APPS)
  File "/home/poppymi2/virtualenv/public_html/app_food/3.11/lib/python3.11/site-packages/django/apps/registry.py", line 83, in populate
    raise RuntimeError("populate() isn't reentrant")
RuntimeError: populate() isn't reentrant
[UID:1745][3158697] Child process with pid: 3158842 was killed by signal: 15, core dumped: no
Traceback (most recent call last):
  File "/home/poppymi2/public_html/app_food/passenger_wsgi.py", line 8, in <module>
    wsgi = imp.load_source('wsgi', 'foodaApp/wsgi.py')
           ^^^^^^^^^^^^^^^^^^^^^^^^^^^^^^^^^^^^^^^^^^^
  File "/opt/alt/python311/lib64/python3.11/imp.py", line 172, in load_source
    module = _load(spec)
             ^^^^^^^^^^^
  File "<frozen importlib._bootstrap>", line 721, in _load
  File "<frozen importlib._bootstrap>", line 690, in _load_unlocked
  File "<frozen importlib._bootstrap_external>", line 940, in exec_module
  File "<frozen importlib._bootstrap>", line 241, in _call_with_frames_removed
  File "foodaApp/wsgi.py", line 16, in <module>
    application = get_wsgi_application()
                  ^^^^^^^^^^^^^^^^^^^^^^
  File "/home/poppymi2/virtualenv/public_html/app_food/3.11/lib/python3.11/site-packages/django/core/wsgi.py", line 12, in get_wsgi_application
    django.setup(set_prefix=False)
  File "/home/poppymi2/virtualenv/public_html/app_food/3.11/lib/python3.11/site-packages/django/__init__.py", line 24, in setup
    apps.populate(settings.INSTALLED_APPS)
  File "/home/poppymi2/virtualenv/public_html/app_food/3.11/lib/python3.11/site-packages/django/apps/registry.py", line 91, in populate
    app_config = AppConfig.create(entry)
                 ^^^^^^^^^^^^^^^^^^^^^^^
  File "/home/poppymi2/virtualenv/public_html/app_food/3.11/lib/python3.11/site-packages/django/apps/config.py", line 193, in create
    import_module(entry)
  File "/opt/alt/python311/lib64/python3.11/importlib/__init__.py", line 126, in import_module
    return _bootstrap._gcd_import(name[level:], package, level)
           ^^^^^^^^^^^^^^^^^^^^^^^^^^^^^^^^^^^^^^^^^^^^^^^^^^^^
  File "<frozen importlib._bootstrap>", line 1204, in _gcd_import
  File "<frozen importlib._bootstrap>", line 1176, in _find_and_load
  File "<frozen importlib._bootstrap>", line 1140, in _find_and_load_unlocked
ModuleNotFoundError: No module named 'translation_manager'
Traceback (most recent call last):
  File "/home/poppymi2/public_html/app_food/passenger_wsgi.py", line 8, in <module>
    wsgi = imp.load_source('wsgi', 'foodaApp/wsgi.py')
           ^^^^^^^^^^^^^^^^^^^^^^^^^^^^^^^^^^^^^^^^^^^
  File "/opt/alt/python311/lib64/python3.11/imp.py", line 172, in load_source
    module = _load(spec)
             ^^^^^^^^^^^
  File "<frozen importlib._bootstrap>", line 721, in _load
  File "<frozen importlib._bootstrap>", line 690, in _load_unlocked
  File "<frozen importlib._bootstrap_external>", line 940, in exec_module
  File "<frozen importlib._bootstrap>", line 241, in _call_with_frames_removed
  File "foodaApp/wsgi.py", line 16, in <module>
    application = get_wsgi_application()
                  ^^^^^^^^^^^^^^^^^^^^^^
  File "/home/poppymi2/virtualenv/public_html/app_food/3.11/lib/python3.11/site-packages/django/core/wsgi.py", line 12, in get_wsgi_application
    django.setup(set_prefix=False)
  File "/home/poppymi2/virtualenv/public_html/app_food/3.11/lib/python3.11/site-packages/django/__init__.py", line 24, in setup
    apps.populate(settings.INSTALLED_APPS)
  File "/home/poppymi2/virtualenv/public_html/app_food/3.11/lib/python3.11/site-packages/django/apps/registry.py", line 83, in populate
    raise RuntimeError("populate() isn't reentrant")
RuntimeError: populate() isn't reentrant
[UID:1745][3160575] Child process with pid: 3160581 was killed by signal: 15, core dumped: no
Traceback (most recent call last):
  File "/home/poppymi2/public_html/app_food/passenger_wsgi.py", line 8, in <module>
    wsgi = imp.load_source('wsgi', 'foodaApp/wsgi.py')
           ^^^^^^^^^^^^^^^^^^^^^^^^^^^^^^^^^^^^^^^^^^^
  File "/opt/alt/python311/lib64/python3.11/imp.py", line 172, in load_source
    module = _load(spec)
             ^^^^^^^^^^^
  File "<frozen importlib._bootstrap>", line 721, in _load
  File "<frozen importlib._bootstrap>", line 690, in _load_unlocked
  File "<frozen importlib._bootstrap_external>", line 940, in exec_module
  File "<frozen importlib._bootstrap>", line 241, in _call_with_frames_removed
  File "foodaApp/wsgi.py", line 16, in <module>
    application = get_wsgi_application()
                  ^^^^^^^^^^^^^^^^^^^^^^
  File "/home/poppymi2/virtualenv/public_html/app_food/3.11/lib/python3.11/site-packages/django/core/wsgi.py", line 12, in get_wsgi_application
    django.setup(set_prefix=False)
  File "/home/poppymi2/virtualenv/public_html/app_food/3.11/lib/python3.11/site-packages/django/__init__.py", line 24, in setup
    apps.populate(settings.INSTALLED_APPS)
  File "/home/poppymi2/virtualenv/public_html/app_food/3.11/lib/python3.11/site-packages/django/apps/registry.py", line 91, in populate
    app_config = AppConfig.create(entry)
                 ^^^^^^^^^^^^^^^^^^^^^^^
  File "/home/poppymi2/virtualenv/public_html/app_food/3.11/lib/python3.11/site-packages/django/apps/config.py", line 193, in create
    import_module(entry)
  File "/opt/alt/python311/lib64/python3.11/importlib/__init__.py", line 126, in import_module
    return _bootstrap._gcd_import(name[level:], package, level)
           ^^^^^^^^^^^^^^^^^^^^^^^^^^^^^^^^^^^^^^^^^^^^^^^^^^^^
  File "<frozen importlib._bootstrap>", line 1204, in _gcd_import
  File "<frozen importlib._bootstrap>", line 1176, in _find_and_load
  File "<frozen importlib._bootstrap>", line 1140, in _find_and_load_unlocked
ModuleNotFoundError: No module named 'translation_manager'
Traceback (most recent call last):
  File "/home/poppymi2/public_html/app_food/passenger_wsgi.py", line 8, in <module>
    wsgi = imp.load_source('wsgi', 'foodaApp/wsgi.py')
           ^^^^^^^^^^^^^^^^^^^^^^^^^^^^^^^^^^^^^^^^^^^
  File "/opt/alt/python311/lib64/python3.11/imp.py", line 172, in load_source
    module = _load(spec)
             ^^^^^^^^^^^
  File "<frozen importlib._bootstrap>", line 721, in _load
  File "<frozen importlib._bootstrap>", line 690, in _load_unlocked
  File "<frozen importlib._bootstrap_external>", line 940, in exec_module
  File "<frozen importlib._bootstrap>", line 241, in _call_with_frames_removed
  File "foodaApp/wsgi.py", line 16, in <module>
    application = get_wsgi_application()
                  ^^^^^^^^^^^^^^^^^^^^^^
  File "/home/poppymi2/virtualenv/public_html/app_food/3.11/lib/python3.11/site-packages/django/core/wsgi.py", line 12, in get_wsgi_application
    django.setup(set_prefix=False)
  File "/home/poppymi2/virtualenv/public_html/app_food/3.11/lib/python3.11/site-packages/django/__init__.py", line 24, in setup
    apps.populate(settings.INSTALLED_APPS)
  File "/home/poppymi2/virtualenv/public_html/app_food/3.11/lib/python3.11/site-packages/django/apps/registry.py", line 83, in populate
    raise RuntimeError("populate() isn't reentrant")
RuntimeError: populate() isn't reentrant
[UID:1745][3164850] Child process with pid: 3164858 was killed by signal: 15, core dumped: no
Traceback (most recent call last):
  File "/home/poppymi2/public_html/app_food/passenger_wsgi.py", line 8, in <module>
    wsgi = imp.load_source('wsgi', 'foodaApp/wsgi.py')
           ^^^^^^^^^^^^^^^^^^^^^^^^^^^^^^^^^^^^^^^^^^^
  File "/opt/alt/python311/lib64/python3.11/imp.py", line 172, in load_source
    module = _load(spec)
             ^^^^^^^^^^^
  File "<frozen importlib._bootstrap>", line 721, in _load
  File "<frozen importlib._bootstrap>", line 690, in _load_unlocked
  File "<frozen importlib._bootstrap_external>", line 940, in exec_module
  File "<frozen importlib._bootstrap>", line 241, in _call_with_frames_removed
  File "foodaApp/wsgi.py", line 16, in <module>
    application = get_wsgi_application()
                  ^^^^^^^^^^^^^^^^^^^^^^
  File "/home/poppymi2/virtualenv/public_html/app_food/3.11/lib/python3.11/site-packages/django/core/wsgi.py", line 12, in get_wsgi_application
    django.setup(set_prefix=False)
  File "/home/poppymi2/virtualenv/public_html/app_food/3.11/lib/python3.11/site-packages/django/__init__.py", line 24, in setup
    apps.populate(settings.INSTALLED_APPS)
  File "/home/poppymi2/virtualenv/public_html/app_food/3.11/lib/python3.11/site-packages/django/apps/registry.py", line 83, in populate
    raise RuntimeError("populate() isn't reentrant")
RuntimeError: populate() isn't reentrant
[UID:1745][3164850] Child process with pid: 3164927 was killed by signal: 15, core dumped: no
Exception while resolving variable 'name' in template 'unknown'.
Traceback (most recent call last):
  File "/home/poppymi2/virtualenv/public_html/app_food/3.11/lib/python3.11/site-packages/django/core/handlers/exception.py", line 56, in inner
    response = get_response(request)
               ^^^^^^^^^^^^^^^^^^^^^
  File "/home/poppymi2/virtualenv/public_html/app_food/3.11/lib/python3.11/site-packages/django/core/handlers/base.py", line 181, in _get_response
    callback, callback_args, callback_kwargs = self.resolve_request(request)
                                               ^^^^^^^^^^^^^^^^^^^^^^^^^^^^^
  File "/home/poppymi2/virtualenv/public_html/app_food/3.11/lib/python3.11/site-packages/django/core/handlers/base.py", line 313, in resolve_request
    resolver_match = resolver.resolve(request.path_info)
                     ^^^^^^^^^^^^^^^^^^^^^^^^^^^^^^^^^^^
  File "/home/poppymi2/virtualenv/public_html/app_food/3.11/lib/python3.11/site-packages/django/urls/resolvers.py", line 702, in resolve
    raise Resolver404({"tried": tried, "path": new_path})
django.urls.exceptions.Resolver404: {'tried': [[<URLResolver <URLPattern list> (admin:admin) 'admin/'>], [<URLPattern 'categorias/' [name='category-list']>], [<URLPattern 'users/' [name='user-list']>], [<URLPattern 'produtos/' [name='product-list']>], [<URLPattern 'novo_pedido/' [name='novo_pedido']>], [<URLPattern 'pagamento_mp/' [name='pagamento_mp']>], [<URLPattern '^imagens/(?P<path>.*)$'>]], 'path': ''}

During handling of the above exception, another exception occurred:

Traceback (most recent call last):
  File "/home/poppymi2/virtualenv/public_html/app_food/3.11/lib/python3.11/site-packages/django/template/base.py", line 880, in _resolve_lookup
    current = current[bit]
              ~~~~~~~^^^^^
TypeError: 'URLResolver' object is not subscriptable

During handling of the above exception, another exception occurred:

Traceback (most recent call last):
  File "/home/poppymi2/virtualenv/public_html/app_food/3.11/lib/python3.11/site-packages/django/template/base.py", line 890, in _resolve_lookup
    current = getattr(current, bit)
              ^^^^^^^^^^^^^^^^^^^^^
AttributeError: 'URLResolver' object has no attribute 'name'

During handling of the above exception, another exception occurred:

Traceback (most recent call last):
  File "/home/poppymi2/virtualenv/public_html/app_food/3.11/lib/python3.11/site-packages/django/template/base.py", line 896, in _resolve_lookup
    current = current[int(bit)]
                      ^^^^^^^^
ValueError: invalid literal for int() with base 10: 'name'

During handling of the above exception, another exception occurred:

Traceback (most recent call last):
  File "/home/poppymi2/virtualenv/public_html/app_food/3.11/lib/python3.11/site-packages/django/template/base.py", line 903, in _resolve_lookup
    raise VariableDoesNotExist(
django.template.base.VariableDoesNotExist: Failed lookup for key [name] in <URLResolver <URLPattern list> (admin:admin) 'admin/'>
Not Found: /app_food/
(0.001) SELECT "categorias_category"."id", "categorias_category"."name" FROM "categorias_category"; args=(); alias=default
Exception while resolving variable 'name' in template 'unknown'.
Traceback (most recent call last):
  File "/home/poppymi2/virtualenv/public_html/app_food/3.11/lib/python3.11/site-packages/django/core/handlers/exception.py", line 56, in inner
    response = get_response(request)
               ^^^^^^^^^^^^^^^^^^^^^
  File "/home/poppymi2/virtualenv/public_html/app_food/3.11/lib/python3.11/site-packages/django/core/handlers/base.py", line 181, in _get_response
    callback, callback_args, callback_kwargs = self.resolve_request(request)
                                               ^^^^^^^^^^^^^^^^^^^^^^^^^^^^^
  File "/home/poppymi2/virtualenv/public_html/app_food/3.11/lib/python3.11/site-packages/django/core/handlers/base.py", line 313, in resolve_request
    resolver_match = resolver.resolve(request.path_info)
                     ^^^^^^^^^^^^^^^^^^^^^^^^^^^^^^^^^^^
  File "/home/poppymi2/virtualenv/public_html/app_food/3.11/lib/python3.11/site-packages/django/urls/resolvers.py", line 702, in resolve
    raise Resolver404({"tried": tried, "path": new_path})
django.urls.exceptions.Resolver404: {'tried': [[<URLResolver <URLPattern list> (admin:admin) 'admin/'>], [<URLPattern 'categorias/' [name='category-list']>], [<URLPattern 'users/' [name='user-list']>], [<URLPattern 'produtos/' [name='product-list']>], [<URLPattern 'novo_pedido/' [name='novo_pedido']>], [<URLPattern 'pagamento_mp/' [name='pagamento_mp']>], [<URLPattern '^imagens/(?P<path>.*)$'>]], 'path': ''}

During handling of the above exception, another exception occurred:

Traceback (most recent call last):
  File "/home/poppymi2/virtualenv/public_html/app_food/3.11/lib/python3.11/site-packages/django/template/base.py", line 880, in _resolve_lookup
    current = current[bit]
              ~~~~~~~^^^^^
TypeError: 'URLResolver' object is not subscriptable

During handling of the above exception, another exception occurred:

Traceback (most recent call last):
  File "/home/poppymi2/virtualenv/public_html/app_food/3.11/lib/python3.11/site-packages/django/template/base.py", line 890, in _resolve_lookup
    current = getattr(current, bit)
              ^^^^^^^^^^^^^^^^^^^^^
AttributeError: 'URLResolver' object has no attribute 'name'

During handling of the above exception, another exception occurred:

Traceback (most recent call last):
  File "/home/poppymi2/virtualenv/public_html/app_food/3.11/lib/python3.11/site-packages/django/template/base.py", line 896, in _resolve_lookup
    current = current[int(bit)]
                      ^^^^^^^^
ValueError: invalid literal for int() with base 10: 'name'

During handling of the above exception, another exception occurred:

Traceback (most recent call last):
  File "/home/poppymi2/virtualenv/public_html/app_food/3.11/lib/python3.11/site-packages/django/template/base.py", line 903, in _resolve_lookup
    raise VariableDoesNotExist(
django.template.base.VariableDoesNotExist: Failed lookup for key [name] in <URLResolver <URLPattern list> (admin:admin) 'admin/'>
Not Found: /app_food/
(0.000) SELECT "produtos_product"."id", "produtos_product"."name", "produtos_product"."descricao", "produtos_product"."preco", "produtos_product"."disponivel", "produtos_product"."meiaPorcao", "produtos_product"."imagem", "produtos_product"."categoria_id" FROM "produtos_product"; args=(); alias=default
Exception while resolving variable 'name' in template 'unknown'.
Traceback (most recent call last):
  File "/home/poppymi2/virtualenv/public_html/app_food/3.11/lib/python3.11/site-packages/django/core/handlers/exception.py", line 56, in inner
    response = get_response(request)
               ^^^^^^^^^^^^^^^^^^^^^
  File "/home/poppymi2/virtualenv/public_html/app_food/3.11/lib/python3.11/site-packages/django/core/handlers/base.py", line 181, in _get_response
    callback, callback_args, callback_kwargs = self.resolve_request(request)
                                               ^^^^^^^^^^^^^^^^^^^^^^^^^^^^^
  File "/home/poppymi2/virtualenv/public_html/app_food/3.11/lib/python3.11/site-packages/django/core/handlers/base.py", line 313, in resolve_request
    resolver_match = resolver.resolve(request.path_info)
                     ^^^^^^^^^^^^^^^^^^^^^^^^^^^^^^^^^^^
  File "/home/poppymi2/virtualenv/public_html/app_food/3.11/lib/python3.11/site-packages/django/urls/resolvers.py", line 702, in resolve
    raise Resolver404({"tried": tried, "path": new_path})
django.urls.exceptions.Resolver404: {'tried': [[<URLResolver <URLPattern list> (admin:admin) 'admin/'>], [<URLPattern 'categorias/' [name='category-list']>], [<URLPattern 'users/' [name='user-list']>], [<URLPattern 'produtos/' [name='product-list']>], [<URLPattern 'novo_pedido/' [name='novo_pedido']>], [<URLPattern 'pagamento_mp/' [name='pagamento_mp']>], [<URLPattern '^imagens/(?P<path>.*)$'>]], 'path': ''}

During handling of the above exception, another exception occurred:

Traceback (most recent call last):
  File "/home/poppymi2/virtualenv/public_html/app_food/3.11/lib/python3.11/site-packages/django/template/base.py", line 880, in _resolve_lookup
    current = current[bit]
              ~~~~~~~^^^^^
TypeError: 'URLResolver' object is not subscriptable

During handling of the above exception, another exception occurred:

Traceback (most recent call last):
  File "/home/poppymi2/virtualenv/public_html/app_food/3.11/lib/python3.11/site-packages/django/template/base.py", line 890, in _resolve_lookup
    current = getattr(current, bit)
              ^^^^^^^^^^^^^^^^^^^^^
AttributeError: 'URLResolver' object has no attribute 'name'

During handling of the above exception, another exception occurred:

Traceback (most recent call last):
  File "/home/poppymi2/virtualenv/public_html/app_food/3.11/lib/python3.11/site-packages/django/template/base.py", line 896, in _resolve_lookup
    current = current[int(bit)]
                      ^^^^^^^^
ValueError: invalid literal for int() with base 10: 'name'

During handling of the above exception, another exception occurred:

Traceback (most recent call last):
  File "/home/poppymi2/virtualenv/public_html/app_food/3.11/lib/python3.11/site-packages/django/template/base.py", line 903, in _resolve_lookup
    raise VariableDoesNotExist(
django.template.base.VariableDoesNotExist: Failed lookup for key [name] in <URLResolver <URLPattern list> (admin:admin) 'admin/'>
Not Found: /app_food/
Exception while resolving variable 'name' in template 'unknown'.
Traceback (most recent call last):
  File "/home/poppymi2/virtualenv/public_html/app_food/3.11/lib/python3.11/site-packages/django/core/handlers/exception.py", line 56, in inner
    response = get_response(request)
               ^^^^^^^^^^^^^^^^^^^^^
  File "/home/poppymi2/virtualenv/public_html/app_food/3.11/lib/python3.11/site-packages/django/core/handlers/base.py", line 181, in _get_response
    callback, callback_args, callback_kwargs = self.resolve_request(request)
                                               ^^^^^^^^^^^^^^^^^^^^^^^^^^^^^
  File "/home/poppymi2/virtualenv/public_html/app_food/3.11/lib/python3.11/site-packages/django/core/handlers/base.py", line 313, in resolve_request
    resolver_match = resolver.resolve(request.path_info)
                     ^^^^^^^^^^^^^^^^^^^^^^^^^^^^^^^^^^^
  File "/home/poppymi2/virtualenv/public_html/app_food/3.11/lib/python3.11/site-packages/django/urls/resolvers.py", line 702, in resolve
    raise Resolver404({"tried": tried, "path": new_path})
django.urls.exceptions.Resolver404: {'tried': [[<URLResolver <URLPattern list> (admin:admin) 'admin/'>], [<URLPattern 'categorias/' [name='category-list']>], [<URLPattern 'users/' [name='user-list']>], [<URLPattern 'produtos/' [name='product-list']>], [<URLPattern 'novo_pedido/' [name='novo_pedido']>], [<URLPattern 'pagamento_mp/' [name='pagamento_mp']>], [<URLPattern '^imagens/(?P<path>.*)$'>]], 'path': ''}

During handling of the above exception, another exception occurred:

Traceback (most recent call last):
  File "/home/poppymi2/virtualenv/public_html/app_food/3.11/lib/python3.11/site-packages/django/template/base.py", line 880, in _resolve_lookup
    current = current[bit]
              ~~~~~~~^^^^^
TypeError: 'URLResolver' object is not subscriptable

During handling of the above exception, another exception occurred:

Traceback (most recent call last):
  File "/home/poppymi2/virtualenv/public_html/app_food/3.11/lib/python3.11/site-packages/django/template/base.py", line 890, in _resolve_lookup
    current = getattr(current, bit)
              ^^^^^^^^^^^^^^^^^^^^^
AttributeError: 'URLResolver' object has no attribute 'name'

During handling of the above exception, another exception occurred:

Traceback (most recent call last):
  File "/home/poppymi2/virtualenv/public_html/app_food/3.11/lib/python3.11/site-packages/django/template/base.py", line 896, in _resolve_lookup
    current = current[int(bit)]
                      ^^^^^^^^
ValueError: invalid literal for int() with base 10: 'name'

During handling of the above exception, another exception occurred:

Traceback (most recent call last):
  File "/home/poppymi2/virtualenv/public_html/app_food/3.11/lib/python3.11/site-packages/django/template/base.py", line 903, in _resolve_lookup
    raise VariableDoesNotExist(
django.template.base.VariableDoesNotExist: Failed lookup for key [name] in <URLResolver <URLPattern list> (admin:admin) 'admin/'>
Not Found: /app_food/
(0.000) SELECT "categorias_category"."id", "categorias_category"."name" FROM "categorias_category"; args=(); alias=default
(0.000) SELECT "produtos_product"."id", "produtos_product"."name", "produtos_product"."descricao", "produtos_product"."preco", "produtos_product"."disponivel", "produtos_product"."meiaPorcao", "produtos_product"."imagem", "produtos_product"."categoria_id" FROM "produtos_product"; args=(); alias=default
Exception while resolving variable 'name' in template 'unknown'.
Traceback (most recent call last):
  File "/home/poppymi2/virtualenv/public_html/app_food/3.11/lib/python3.11/site-packages/django/core/handlers/exception.py", line 56, in inner
    response = get_response(request)
               ^^^^^^^^^^^^^^^^^^^^^
  File "/home/poppymi2/virtualenv/public_html/app_food/3.11/lib/python3.11/site-packages/django/core/handlers/base.py", line 181, in _get_response
    callback, callback_args, callback_kwargs = self.resolve_request(request)
                                               ^^^^^^^^^^^^^^^^^^^^^^^^^^^^^
  File "/home/poppymi2/virtualenv/public_html/app_food/3.11/lib/python3.11/site-packages/django/core/handlers/base.py", line 313, in resolve_request
    resolver_match = resolver.resolve(request.path_info)
                     ^^^^^^^^^^^^^^^^^^^^^^^^^^^^^^^^^^^
  File "/home/poppymi2/virtualenv/public_html/app_food/3.11/lib/python3.11/site-packages/django/urls/resolvers.py", line 702, in resolve
    raise Resolver404({"tried": tried, "path": new_path})
django.urls.exceptions.Resolver404: {'tried': [[<URLResolver <URLPattern list> (admin:admin) 'admin/'>], [<URLPattern 'categorias/' [name='category-list']>], [<URLPattern 'users/' [name='user-list']>], [<URLPattern 'produtos/' [name='product-list']>], [<URLPattern 'novo_pedido/' [name='novo_pedido']>], [<URLPattern 'pagamento_mp/' [name='pagamento_mp']>], [<URLPattern '^imagens/(?P<path>.*)$'>]], 'path': 'pedidos/'}

During handling of the above exception, another exception occurred:

Traceback (most recent call last):
  File "/home/poppymi2/virtualenv/public_html/app_food/3.11/lib/python3.11/site-packages/django/template/base.py", line 880, in _resolve_lookup
    current = current[bit]
              ~~~~~~~^^^^^
TypeError: 'URLResolver' object is not subscriptable

During handling of the above exception, another exception occurred:

Traceback (most recent call last):
  File "/home/poppymi2/virtualenv/public_html/app_food/3.11/lib/python3.11/site-packages/django/template/base.py", line 890, in _resolve_lookup
    current = getattr(current, bit)
              ^^^^^^^^^^^^^^^^^^^^^
AttributeError: 'URLResolver' object has no attribute 'name'

During handling of the above exception, another exception occurred:

Traceback (most recent call last):
  File "/home/poppymi2/virtualenv/public_html/app_food/3.11/lib/python3.11/site-packages/django/template/base.py", line 896, in _resolve_lookup
    current = current[int(bit)]
                      ^^^^^^^^
ValueError: invalid literal for int() with base 10: 'name'

During handling of the above exception, another exception occurred:

Traceback (most recent call last):
  File "/home/poppymi2/virtualenv/public_html/app_food/3.11/lib/python3.11/site-packages/django/template/base.py", line 903, in _resolve_lookup
    raise VariableDoesNotExist(
django.template.base.VariableDoesNotExist: Failed lookup for key [name] in <URLResolver <URLPattern list> (admin:admin) 'admin/'>
Not Found: /app_food/pedidos/
Exception while resolving variable 'name' in template 'unknown'.
Traceback (most recent call last):
  File "/home/poppymi2/virtualenv/public_html/app_food/3.11/lib/python3.11/site-packages/django/core/handlers/exception.py", line 56, in inner
    response = get_response(request)
               ^^^^^^^^^^^^^^^^^^^^^
  File "/home/poppymi2/virtualenv/public_html/app_food/3.11/lib/python3.11/site-packages/django/core/handlers/base.py", line 181, in _get_response
    callback, callback_args, callback_kwargs = self.resolve_request(request)
                                               ^^^^^^^^^^^^^^^^^^^^^^^^^^^^^
  File "/home/poppymi2/virtualenv/public_html/app_food/3.11/lib/python3.11/site-packages/django/core/handlers/base.py", line 313, in resolve_request
    resolver_match = resolver.resolve(request.path_info)
                     ^^^^^^^^^^^^^^^^^^^^^^^^^^^^^^^^^^^
  File "/home/poppymi2/virtualenv/public_html/app_food/3.11/lib/python3.11/site-packages/django/urls/resolvers.py", line 702, in resolve
    raise Resolver404({"tried": tried, "path": new_path})
django.urls.exceptions.Resolver404: {'tried': [[<URLResolver <URLPattern list> (admin:admin) 'admin/'>], [<URLPattern 'categorias/' [name='category-list']>], [<URLPattern 'users/' [name='user-list']>], [<URLPattern 'produtos/' [name='product-list']>], [<URLPattern 'novo_pedido/' [name='novo_pedido']>], [<URLPattern 'pagamento_mp/' [name='pagamento_mp']>], [<URLPattern '^imagens/(?P<path>.*)$'>]], 'path': ''}

During handling of the above exception, another exception occurred:

Traceback (most recent call last):
  File "/home/poppymi2/virtualenv/public_html/app_food/3.11/lib/python3.11/site-packages/django/template/base.py", line 880, in _resolve_lookup
    current = current[bit]
              ~~~~~~~^^^^^
TypeError: 'URLResolver' object is not subscriptable

During handling of the above exception, another exception occurred:

Traceback (most recent call last):
  File "/home/poppymi2/virtualenv/public_html/app_food/3.11/lib/python3.11/site-packages/django/template/base.py", line 890, in _resolve_lookup
    current = getattr(current, bit)
              ^^^^^^^^^^^^^^^^^^^^^
AttributeError: 'URLResolver' object has no attribute 'name'

During handling of the above exception, another exception occurred:

Traceback (most recent call last):
  File "/home/poppymi2/virtualenv/public_html/app_food/3.11/lib/python3.11/site-packages/django/template/base.py", line 896, in _resolve_lookup
    current = current[int(bit)]
                      ^^^^^^^^
ValueError: invalid literal for int() with base 10: 'name'

During handling of the above exception, another exception occurred:

Traceback (most recent call last):
  File "/home/poppymi2/virtualenv/public_html/app_food/3.11/lib/python3.11/site-packages/django/template/base.py", line 903, in _resolve_lookup
    raise VariableDoesNotExist(
django.template.base.VariableDoesNotExist: Failed lookup for key [name] in <URLResolver <URLPattern list> (admin:admin) 'admin/'>
Not Found: /app_food/
Exception while resolving variable 'name' in template 'unknown'.
Traceback (most recent call last):
  File "/home/poppymi2/virtualenv/public_html/app_food/3.11/lib/python3.11/site-packages/django/core/handlers/exception.py", line 56, in inner
    response = get_response(request)
               ^^^^^^^^^^^^^^^^^^^^^
  File "/home/poppymi2/virtualenv/public_html/app_food/3.11/lib/python3.11/site-packages/django/core/handlers/base.py", line 181, in _get_response
    callback, callback_args, callback_kwargs = self.resolve_request(request)
                                               ^^^^^^^^^^^^^^^^^^^^^^^^^^^^^
  File "/home/poppymi2/virtualenv/public_html/app_food/3.11/lib/python3.11/site-packages/django/core/handlers/base.py", line 313, in resolve_request
    resolver_match = resolver.resolve(request.path_info)
                     ^^^^^^^^^^^^^^^^^^^^^^^^^^^^^^^^^^^
  File "/home/poppymi2/virtualenv/public_html/app_food/3.11/lib/python3.11/site-packages/django/urls/resolvers.py", line 702, in resolve
    raise Resolver404({"tried": tried, "path": new_path})
django.urls.exceptions.Resolver404: {'tried': [[<URLResolver <URLPattern list> (admin:admin) 'admin/'>], [<URLPattern 'categorias/' [name='category-list']>], [<URLPattern 'users/' [name='user-list']>], [<URLPattern 'produtos/' [name='product-list']>], [<URLPattern 'novo_pedido/' [name='novo_pedido']>], [<URLPattern 'pagamento_mp/' [name='pagamento_mp']>], [<URLPattern '^imagens/(?P<path>.*)$'>]], 'path': ''}

During handling of the above exception, another exception occurred:

Traceback (most recent call last):
  File "/home/poppymi2/virtualenv/public_html/app_food/3.11/lib/python3.11/site-packages/django/template/base.py", line 880, in _resolve_lookup
    current = current[bit]
              ~~~~~~~^^^^^
TypeError: 'URLResolver' object is not subscriptable

During handling of the above exception, another exception occurred:

Traceback (most recent call last):
  File "/home/poppymi2/virtualenv/public_html/app_food/3.11/lib/python3.11/site-packages/django/template/base.py", line 890, in _resolve_lookup
    current = getattr(current, bit)
              ^^^^^^^^^^^^^^^^^^^^^
AttributeError: 'URLResolver' object has no attribute 'name'

During handling of the above exception, another exception occurred:

Traceback (most recent call last):
  File "/home/poppymi2/virtualenv/public_html/app_food/3.11/lib/python3.11/site-packages/django/template/base.py", line 896, in _resolve_lookup
    current = current[int(bit)]
                      ^^^^^^^^
ValueError: invalid literal for int() with base 10: 'name'

During handling of the above exception, another exception occurred:

Traceback (most recent call last):
  File "/home/poppymi2/virtualenv/public_html/app_food/3.11/lib/python3.11/site-packages/django/template/base.py", line 903, in _resolve_lookup
    raise VariableDoesNotExist(
django.template.base.VariableDoesNotExist: Failed lookup for key [name] in <URLResolver <URLPattern list> (admin:admin) 'admin/'>
Not Found: /app_food/
(0.001) SELECT "categorias_category"."id", "categorias_category"."name" FROM "categorias_category"; args=(); alias=default
Exception while resolving variable 'name' in template 'unknown'.
Traceback (most recent call last):
  File "/home/poppymi2/virtualenv/public_html/app_food/3.11/lib/python3.11/site-packages/django/core/handlers/exception.py", line 56, in inner
    response = get_response(request)
               ^^^^^^^^^^^^^^^^^^^^^
  File "/home/poppymi2/virtualenv/public_html/app_food/3.11/lib/python3.11/site-packages/django/core/handlers/base.py", line 181, in _get_response
    callback, callback_args, callback_kwargs = self.resolve_request(request)
                                               ^^^^^^^^^^^^^^^^^^^^^^^^^^^^^
  File "/home/poppymi2/virtualenv/public_html/app_food/3.11/lib/python3.11/site-packages/django/core/handlers/base.py", line 313, in resolve_request
    resolver_match = resolver.resolve(request.path_info)
                     ^^^^^^^^^^^^^^^^^^^^^^^^^^^^^^^^^^^
  File "/home/poppymi2/virtualenv/public_html/app_food/3.11/lib/python3.11/site-packages/django/urls/resolvers.py", line 702, in resolve
    raise Resolver404({"tried": tried, "path": new_path})
django.urls.exceptions.Resolver404: {'tried': [[<URLResolver <URLPattern list> (admin:admin) 'admin1/'>], [<URLPattern 'categorias/' [name='category-list']>], [<URLPattern 'users/' [name='user-list']>], [<URLPattern 'produtos/' [name='product-list']>], [<URLPattern 'novo_pedido/' [name='novo_pedido']>], [<URLPattern 'pagamento_mp/' [name='pagamento_mp']>], [<URLPattern '^imagens/(?P<path>.*)$'>]], 'path': ''}

During handling of the above exception, another exception occurred:

Traceback (most recent call last):
  File "/home/poppymi2/virtualenv/public_html/app_food/3.11/lib/python3.11/site-packages/django/template/base.py", line 880, in _resolve_lookup
    current = current[bit]
              ~~~~~~~^^^^^
TypeError: 'URLResolver' object is not subscriptable

During handling of the above exception, another exception occurred:

Traceback (most recent call last):
  File "/home/poppymi2/virtualenv/public_html/app_food/3.11/lib/python3.11/site-packages/django/template/base.py", line 890, in _resolve_lookup
    current = getattr(current, bit)
              ^^^^^^^^^^^^^^^^^^^^^
AttributeError: 'URLResolver' object has no attribute 'name'

During handling of the above exception, another exception occurred:

Traceback (most recent call last):
  File "/home/poppymi2/virtualenv/public_html/app_food/3.11/lib/python3.11/site-packages/django/template/base.py", line 896, in _resolve_lookup
    current = current[int(bit)]
                      ^^^^^^^^
ValueError: invalid literal for int() with base 10: 'name'

During handling of the above exception, another exception occurred:

Traceback (most recent call last):
  File "/home/poppymi2/virtualenv/public_html/app_food/3.11/lib/python3.11/site-packages/django/template/base.py", line 903, in _resolve_lookup
    raise VariableDoesNotExist(
django.template.base.VariableDoesNotExist: Failed lookup for key [name] in <URLResolver <URLPattern list> (admin:admin) 'admin1/'>
Not Found: /app_food/
Exception while resolving variable 'name' in template 'unknown'.
Traceback (most recent call last):
  File "/home/poppymi2/virtualenv/public_html/app_food/3.11/lib/python3.11/site-packages/django/core/handlers/exception.py", line 56, in inner
    response = get_response(request)
               ^^^^^^^^^^^^^^^^^^^^^
  File "/home/poppymi2/virtualenv/public_html/app_food/3.11/lib/python3.11/site-packages/django/core/handlers/base.py", line 181, in _get_response
    callback, callback_args, callback_kwargs = self.resolve_request(request)
                                               ^^^^^^^^^^^^^^^^^^^^^^^^^^^^^
  File "/home/poppymi2/virtualenv/public_html/app_food/3.11/lib/python3.11/site-packages/django/core/handlers/base.py", line 313, in resolve_request
    resolver_match = resolver.resolve(request.path_info)
                     ^^^^^^^^^^^^^^^^^^^^^^^^^^^^^^^^^^^
  File "/home/poppymi2/virtualenv/public_html/app_food/3.11/lib/python3.11/site-packages/django/urls/resolvers.py", line 702, in resolve
    raise Resolver404({"tried": tried, "path": new_path})
django.urls.exceptions.Resolver404: {'tried': [[<URLResolver <URLPattern list> (admin:admin) 'admin1/'>], [<URLPattern 'categorias/' [name='category-list']>], [<URLPattern 'users/' [name='user-list']>], [<URLPattern 'produtos/' [name='product-list']>], [<URLPattern 'novo_pedido/' [name='novo_pedido']>], [<URLPattern 'pagamento_mp/' [name='pagamento_mp']>], [<URLPattern '^imagens/(?P<path>.*)$'>]], 'path': ''}

During handling of the above exception, another exception occurred:

Traceback (most recent call last):
  File "/home/poppymi2/virtualenv/public_html/app_food/3.11/lib/python3.11/site-packages/django/template/base.py", line 880, in _resolve_lookup
    current = current[bit]
              ~~~~~~~^^^^^
TypeError: 'URLResolver' object is not subscriptable

During handling of the above exception, another exception occurred:

Traceback (most recent call last):
  File "/home/poppymi2/virtualenv/public_html/app_food/3.11/lib/python3.11/site-packages/django/template/base.py", line 890, in _resolve_lookup
    current = getattr(current, bit)
              ^^^^^^^^^^^^^^^^^^^^^
AttributeError: 'URLResolver' object has no attribute 'name'

During handling of the above exception, another exception occurred:

Traceback (most recent call last):
  File "/home/poppymi2/virtualenv/public_html/app_food/3.11/lib/python3.11/site-packages/django/template/base.py", line 896, in _resolve_lookup
    current = current[int(bit)]
                      ^^^^^^^^
ValueError: invalid literal for int() with base 10: 'name'

During handling of the above exception, another exception occurred:

Traceback (most recent call last):
  File "/home/poppymi2/virtualenv/public_html/app_food/3.11/lib/python3.11/site-packages/django/template/base.py", line 903, in _resolve_lookup
    raise VariableDoesNotExist(
django.template.base.VariableDoesNotExist: Failed lookup for key [name] in <URLResolver <URLPattern list> (admin:admin) 'admin1/'>
Not Found: /app_food/
(0.001) SELECT "categorias_category"."id", "categorias_category"."name" FROM "categorias_category"; args=(); alias=default
Exception while resolving variable 'name' in template 'unknown'.
Traceback (most recent call last):
  File "/home/poppymi2/virtualenv/public_html/app_food/3.11/lib/python3.11/site-packages/django/core/handlers/exception.py", line 56, in inner
    response = get_response(request)
               ^^^^^^^^^^^^^^^^^^^^^
  File "/home/poppymi2/virtualenv/public_html/app_food/3.11/lib/python3.11/site-packages/django/core/handlers/base.py", line 181, in _get_response
    callback, callback_args, callback_kwargs = self.resolve_request(request)
                                               ^^^^^^^^^^^^^^^^^^^^^^^^^^^^^
  File "/home/poppymi2/virtualenv/public_html/app_food/3.11/lib/python3.11/site-packages/django/core/handlers/base.py", line 313, in resolve_request
    resolver_match = resolver.resolve(request.path_info)
                     ^^^^^^^^^^^^^^^^^^^^^^^^^^^^^^^^^^^
  File "/home/poppymi2/virtualenv/public_html/app_food/3.11/lib/python3.11/site-packages/django/urls/resolvers.py", line 702, in resolve
    raise Resolver404({"tried": tried, "path": new_path})
django.urls.exceptions.Resolver404: {'tried': [[<URLResolver <URLPattern list> (admin:admin) 'admin1/'>], [<URLPattern 'categorias/' [name='category-list']>], [<URLPattern 'users/' [name='user-list']>], [<URLPattern 'produtos/' [name='product-list']>], [<URLPattern 'novo_pedido/' [name='novo_pedido']>], [<URLPattern 'pagamento_mp/' [name='pagamento_mp']>], [<URLPattern '^imagens/(?P<path>.*)$'>]], 'path': ''}

During handling of the above exception, another exception occurred:

Traceback (most recent call last):
  File "/home/poppymi2/virtualenv/public_html/app_food/3.11/lib/python3.11/site-packages/django/template/base.py", line 880, in _resolve_lookup
    current = current[bit]
              ~~~~~~~^^^^^
TypeError: 'URLResolver' object is not subscriptable

During handling of the above exception, another exception occurred:

Traceback (most recent call last):
  File "/home/poppymi2/virtualenv/public_html/app_food/3.11/lib/python3.11/site-packages/django/template/base.py", line 890, in _resolve_lookup
    current = getattr(current, bit)
              ^^^^^^^^^^^^^^^^^^^^^
AttributeError: 'URLResolver' object has no attribute 'name'

During handling of the above exception, another exception occurred:

Traceback (most recent call last):
  File "/home/poppymi2/virtualenv/public_html/app_food/3.11/lib/python3.11/site-packages/django/template/base.py", line 896, in _resolve_lookup
    current = current[int(bit)]
                      ^^^^^^^^
ValueError: invalid literal for int() with base 10: 'name'

During handling of the above exception, another exception occurred:

Traceback (most recent call last):
  File "/home/poppymi2/virtualenv/public_html/app_food/3.11/lib/python3.11/site-packages/django/template/base.py", line 903, in _resolve_lookup
    raise VariableDoesNotExist(
django.template.base.VariableDoesNotExist: Failed lookup for key [name] in <URLResolver <URLPattern list> (admin:admin) 'admin1/'>
Not Found: /app_food/
Exception while resolving variable 'name' in template 'unknown'.
Traceback (most recent call last):
  File "/home/poppymi2/virtualenv/public_html/app_food/3.11/lib/python3.11/site-packages/django/core/handlers/exception.py", line 56, in inner
    response = get_response(request)
               ^^^^^^^^^^^^^^^^^^^^^
  File "/home/poppymi2/virtualenv/public_html/app_food/3.11/lib/python3.11/site-packages/django/core/handlers/base.py", line 181, in _get_response
    callback, callback_args, callback_kwargs = self.resolve_request(request)
                                               ^^^^^^^^^^^^^^^^^^^^^^^^^^^^^
  File "/home/poppymi2/virtualenv/public_html/app_food/3.11/lib/python3.11/site-packages/django/core/handlers/base.py", line 313, in resolve_request
    resolver_match = resolver.resolve(request.path_info)
                     ^^^^^^^^^^^^^^^^^^^^^^^^^^^^^^^^^^^
  File "/home/poppymi2/virtualenv/public_html/app_food/3.11/lib/python3.11/site-packages/django/urls/resolvers.py", line 702, in resolve
    raise Resolver404({"tried": tried, "path": new_path})
django.urls.exceptions.Resolver404: {'tried': [[<URLResolver <URLPattern list> (admin:admin) 'admin1/'>], [<URLPattern 'categorias/' [name='category-list']>], [<URLPattern 'users/' [name='user-list']>], [<URLPattern 'produtos/' [name='product-list']>], [<URLPattern 'novo_pedido/' [name='novo_pedido']>], [<URLPattern 'pagamento_mp/' [name='pagamento_mp']>], [<URLPattern '^imagens/(?P<path>.*)$'>]], 'path': ''}

During handling of the above exception, another exception occurred:

Traceback (most recent call last):
  File "/home/poppymi2/virtualenv/public_html/app_food/3.11/lib/python3.11/site-packages/django/template/base.py", line 880, in _resolve_lookup
    current = current[bit]
              ~~~~~~~^^^^^
TypeError: 'URLResolver' object is not subscriptable

During handling of the above exception, another exception occurred:

Traceback (most recent call last):
  File "/home/poppymi2/virtualenv/public_html/app_food/3.11/lib/python3.11/site-packages/django/template/base.py", line 890, in _resolve_lookup
    current = getattr(current, bit)
              ^^^^^^^^^^^^^^^^^^^^^
AttributeError: 'URLResolver' object has no attribute 'name'

During handling of the above exception, another exception occurred:

Traceback (most recent call last):
  File "/home/poppymi2/virtualenv/public_html/app_food/3.11/lib/python3.11/site-packages/django/template/base.py", line 896, in _resolve_lookup
    current = current[int(bit)]
                      ^^^^^^^^
ValueError: invalid literal for int() with base 10: 'name'

During handling of the above exception, another exception occurred:

Traceback (most recent call last):
  File "/home/poppymi2/virtualenv/public_html/app_food/3.11/lib/python3.11/site-packages/django/template/base.py", line 903, in _resolve_lookup
    raise VariableDoesNotExist(
django.template.base.VariableDoesNotExist: Failed lookup for key [name] in <URLResolver <URLPattern list> (admin:admin) 'admin1/'>
Not Found: /app_food/
Exception while resolving variable 'name' in template 'unknown'.
Traceback (most recent call last):
  File "/home/poppymi2/virtualenv/public_html/app_food/3.11/lib/python3.11/site-packages/django/core/handlers/exception.py", line 56, in inner
    response = get_response(request)
               ^^^^^^^^^^^^^^^^^^^^^
  File "/home/poppymi2/virtualenv/public_html/app_food/3.11/lib/python3.11/site-packages/django/core/handlers/base.py", line 181, in _get_response
    callback, callback_args, callback_kwargs = self.resolve_request(request)
                                               ^^^^^^^^^^^^^^^^^^^^^^^^^^^^^
  File "/home/poppymi2/virtualenv/public_html/app_food/3.11/lib/python3.11/site-packages/django/core/handlers/base.py", line 313, in resolve_request
    resolver_match = resolver.resolve(request.path_info)
                     ^^^^^^^^^^^^^^^^^^^^^^^^^^^^^^^^^^^
  File "/home/poppymi2/virtualenv/public_html/app_food/3.11/lib/python3.11/site-packages/django/urls/resolvers.py", line 702, in resolve
    raise Resolver404({"tried": tried, "path": new_path})
django.urls.exceptions.Resolver404: {'tried': [[<URLResolver <URLPattern list> (admin:admin) 'admin1/'>], [<URLPattern 'categorias/' [name='category-list']>], [<URLPattern 'users/' [name='user-list']>], [<URLPattern 'produtos/' [name='product-list']>], [<URLPattern 'novo_pedido/' [name='novo_pedido']>], [<URLPattern 'pagamento_mp/' [name='pagamento_mp']>], [<URLPattern '^imagens/(?P<path>.*)$'>]], 'path': ''}

During handling of the above exception, another exception occurred:

Traceback (most recent call last):
  File "/home/poppymi2/virtualenv/public_html/app_food/3.11/lib/python3.11/site-packages/django/template/base.py", line 880, in _resolve_lookup
    current = current[bit]
              ~~~~~~~^^^^^
TypeError: 'URLResolver' object is not subscriptable

During handling of the above exception, another exception occurred:

Traceback (most recent call last):
  File "/home/poppymi2/virtualenv/public_html/app_food/3.11/lib/python3.11/site-packages/django/template/base.py", line 890, in _resolve_lookup
    current = getattr(current, bit)
              ^^^^^^^^^^^^^^^^^^^^^
AttributeError: 'URLResolver' object has no attribute 'name'

During handling of the above exception, another exception occurred:

Traceback (most recent call last):
  File "/home/poppymi2/virtualenv/public_html/app_food/3.11/lib/python3.11/site-packages/django/template/base.py", line 896, in _resolve_lookup
    current = current[int(bit)]
                      ^^^^^^^^
ValueError: invalid literal for int() with base 10: 'name'

During handling of the above exception, another exception occurred:

Traceback (most recent call last):
  File "/home/poppymi2/virtualenv/public_html/app_food/3.11/lib/python3.11/site-packages/django/template/base.py", line 903, in _resolve_lookup
    raise VariableDoesNotExist(
django.template.base.VariableDoesNotExist: Failed lookup for key [name] in <URLResolver <URLPattern list> (admin:admin) 'admin1/'>
Not Found: /app_food/
(0.001) SELECT "categorias_category"."id", "categorias_category"."name" FROM "categorias_category"; args=(); alias=default
